Workbook

Sheet Sources
A2: Singapore Strat monthly import | B2: Kpler view. Show imports for Singapore strait, LSFO and VLSFO product only actual, exclude intra-region flows, split by origin countries, monthly. Export
B3: Depending on where you are in the month, start vs end, go through individual country exports and assess what the final month tally might look like.
B4: Set forward view for specific countries based on TARs and Rumours. Ad-hoc column available for issues such as dangote.
A6: Singapore Strait exports | B6: Kpler view. Show exports for Singapore strait, LSFO and VLSFO product only actual, exclude intra-region flows, split by destination countries, monthly. Export
B7: Depending on where you are in the month, start vs end, go through individual country exports and assess what the final month tally might look like.
B8: Set forward view for specific countries based on TARs and Rumours. Ad-hoc column available for issues such as dangote.
A10: Bunker Sales | B10: Updated monthly with values from Singapore government website
B11: To potentially be replaced by the Ship & Bunker or Spot Barge subscription
A13: Crude imports | B13: Kpler crude imports, actual, exclude intra company flows, split by grades, select the following grades only, | L13: Dar | M13: Ostra | N13: Vincent | O13: Atlanta | P13: Kraken | Q13: Nile | R13: Doba Blend | S13: Pyrenees | T13: Van Gogh | U13: Yombo | V13: Meleck | W13: Escalante
A15: Production | B15: Run JODI update and draw latest month update from there for Singapore, Malaysia and Indonesia
A17: Storage Onshore | B17: Weekly data taken from Platts Connect website, using the code SSGP599, or bloomberg code SPIVRESD Index
A19: Floating Storage | B19: Kpler Floating storage report. For Malacca Strait and Singapore Strait, Floating Storage, Cargo Quantity, LSVGO LSFO VLSFO LSSRFO, for Vessel class VLCC

Sheet Singapore Strait monthly import
A1: date | B1: Total | C1: Ad-hoc | D1: Brazil | E1: Malaysia | F1: Indonesia | G1: Netherlands | H1: Kuwait | I1: Thailand | J1: Singapore Republic | K1: Japan | L1: India | M1: Denmark | N1: Turkey | O1: Taiwan | P1: South Korea | Q1: Estonia | R1: United States | S1: Vietnam | T1: Spain | U1: United Arab Emirates | V1: Russian Federation | W1: Belgium | X1: Malta | Y1: Greece | Z1: France | AA1: Bahamas | AB1: Italy | AC1: China | AD1: Sweden | AE1: Georgia | AF1: Australia | AG1: Pakistan | AH1: Sint Eustatius | AI1: United Kingdom | AJ1: Portugal | AK1: Israel | AL1: Chile | AM1: Germany | AN1: Algeria | AO1: Argentina | AP1: New Zealand | AQ1: Cyprus | AR1: Mexico | AS1: Croatia | AT1: Peru | AU1: Libya | AV1: Ireland | AW1: South Africa | AX1: Tunisia | AY1: Ukraine | AZ1: Philippines | BA1: Egypt | BB1: Romania | BC1: Qatar | BD1: Norway | BE1: Unknown
A2: date | B2: =SUM(C2:XFD2) -> 2369.8216 | D2: 511.43924 | E2: 738.3602 | F2: 26.830563 | G2: 116.88265 | H2: 0 | I2: 72.204675 | J2: 38.594433 | K2: 49.08111 | L2: 92.682558 | M2: 0 | N2: 0 | O2: 146.28282 | P2: 0 | Q2: 37.506489 | R2: 24.551967 | S2: 6.713109 | T2: 0 | U2: 76.376712 | V2: 120.59536 | W2: 0 | X2: 0 | Y2: 39.188808 | Z2: 0 | AA2: 61.56774 | AB2: 59.19975 | AC2: 0 | AD2: 34.542222 | AE2: 0 | AF2: 0 | AG2: 0 | AH2: 0 | AI2: 0 | AJ2: 0 | AK2: 0 | AL2: 0 | AM2: 0 | AN2: 0 | AO2: 0 | AP2: 0 | AQ2: 0 | AR2: 73.87368 | AS2: 0 | AT2: 0 | AU2: 0 | AV2: 0 | AW2: 0 | AX2: 0 | AY2: 35.945898 | AZ2: 0 | BA2: 0 | BB2: 0 | BC2: 0 | BD2: 7.401633 | BE2: 0
A3: 2021-04 | B3: =SUM(C3:XFD3) -> 1965.4136 | D3: 233.26508 | E3: 425.17118 | F3: 59.341449 | G3: 0 | H3: 0 | I3: 197.10046 | J3: 218.12992 | K3: 50.96409 | L3: 93.769551 | M3: 0 | N3: 0 | O3: 105.20437 | P3: 0 | Q3: 0 | R3: 86.535294 | S3: 6.713109 | T3: 0 | U3: 0 | V3: 158.11897 | W3: 0 | X3: 0 | Y3: 49.288428 | Z3: 0 | AA3: 215.17326 | AB3: 0 | AC3: 0 | AD3: 0 | AE3: 40.934844 | AF3: 0 | AG3: 0 | AH3: 0 | AI3: 25.703599 | AJ3: 0 | AK3: 0 | AL3: 0 | AM3: 0 | AN3: 0 | AO3: 0 | AP3: 0 | AQ3: 0 | AR3: 0 | AS3: 0 | AT3: 0 | AU3: 0 | AV3: 0 | AW3: 0 | AX3: 0 | AY3: 0 | AZ3: 0 | BA3: 0 | BB3: 0 | BC3: 0 | BD3: 0 | BE3: 0
A4: 2021-05 | B4: =SUM(C4:XFD4) -> 2480.4477 | D4: 375.53278 | E4: 551.13303 | F4: 62.559633 | G4: 216.60071 | H4: 0 | I4: 95.333946 | J4: 126.36698 | K4: 0 | L4: 70.967424 | M4: 89.312214 | N4: 65.66655 | O4: 156.78186 | P4: 0 | Q4: 96.800388 | R4: 0 | S4: 15.470868 | T4: 116.37387 | U4: 17.55546 | V4: 30.749634 | W4: 0 | X4: 202.10747 | Y4: 0 | Z4: 0 | AA4: 177.00012 | AB4: 14.134713 | AC4: 0 | AD4: 0 | AE4: 0 | AF4: 0 | AG4: 0 | AH4: 0 | AI4: 0 | AJ4: 0 | AK4: 0 | AL4: 0 | AM4: 0 | AN4: 0 | AO4: 0 | AP4: 0 | AQ4: 0 | AR4: 0 | AS4: 0 | AT4: 0 | AU4: 0 | AV4: 0 | AW4: 0 | AX4: 0 | AY4: 0 | AZ4: 0 | BA4: 0 | BB4: 0 | BC4: 0 | BD4: 0 | BE4: 0
A5: 2021-06 | B5: =SUM(C5:XFD5) -> 2021.7271 | D5: 139.99956 | E5: 698.59699 | F5: 111.53803 | G5: 73.133802 | H5: 0 | I5: 114.12571 | J5: 68.070678 | K5: 0 | L5: 94.030125 | M5: 30.238947 | N5: 0 | O5: 88.824351 | P5: 12.992562 | Q5: 0 | R5: 0 | S5: 23.355609 | T5: 0 | U5: 0 | V5: 39.854508 | W5: 0 | X5: 39.003363 | Y5: 0 | Z5: 0 | AA5: 83.999928 | AB5: 137.59829 | AC5: 0 | AD5: 0 | AE5: 0 | AF5: 0 | AG5: 0 | AH5: 157.34866 | AI5: 0 | AJ5: 0 | AK5: 0 | AL5: 39.404685 | AM5: 0 | AN5: 54.324924 | AO5: 0 | AP5: 0 | AQ5: 0 | AR5: 0 | AS5: 0 | AT5: 0 | AU5: 0 | AV5: 0 | AW5: 0 | AX5: 0 | AY5: 0 | AZ5: 0 | BA5: 15.286374 | BB5: 0 | BC5: 0 | BD5: 0 | BE5: 0
A6: 2021-07 | B6: =SUM(C6:XFD6) -> 2549.106 | D6: 435.88039 | E6: 528.96427 | F6: 36.598284 | G6: 188.86099 | H6: 0 | I6: 230.91707 | J6: 68.562345 | K6: 0 | L6: 45.99987 | M6: 98.279193 | N6: 0 | O6: 0 | P6: 47.000322 | Q6: 70.799097 | R6: 207.40549 | S6: 6.713109 | T6: 62.808795 | U6: 157.89263 | V6: 39.302928 | W6: 42.768372 | X6: 75.088107 | Y6: 0 | Z6: 0 | AA6: 28.18764 | AB6: 44.198676 | AC6: 0 | AD6: 0 | AE6: 0 | AF6: 0 | AG6: 0 | AH6: 0 | AI6: 30.678309 | AJ6: 89.613681 | AK6: 0 | AL6: 0 | AM6: 0 | AN6: 0 | AO6: 0 | AP6: 0 | AQ6: 0 | AR6: 0 | AS6: 0 | AT6: 0 | AU6: 0 | AV6: 0 | AW6: 0 | AX6: 12.586485 | AY6: 0 | AZ6: 0 | BA6: 0 | BB6: 0 | BC6: 0 | BD6: 0 | BE6: 0
A7: 2021-08 | B7: =SUM(C7:XFD7) -> 2645.7647 | D7: 234.55369 | E7: 457.28169 | F7: 125.92762 | G7: 250.69216 | H7: 0 | I7: 149.42587 | J7: 130.88708 | K7: 166.33275 | L7: 114.63544 | M7: 282.28818 | N7: 0 | O7: 25.994634 | P7: 96.272583 | Q7: 60.424638 | R7: 115.45235 | S7: 1.815459 | T7: 0 | U7: 0 | V7: 0 | W7: 106.73263 | X7: 180.85833 | Y7: 0 | Z7: 0 | AA7: 0 | AB7: 41.261037 | AC7: 35.955408 | AD7: 39.301977 | AE7: 0 | AF7: 29.6712 | AG7: 0 | AH7: 0 | AI7: 0 | AJ7: 0 | AK7: 0 | AL7: 0 | AM7: 0 | AN7: 0 | AO7: 0 | AP7: 0 | AQ7: 0 | AR7: 0 | AS7: 0 | AT7: 0 | AU7: 0 | AV7: 0 | AW7: 0 | AX7: 0 | AY7: 0 | AZ7: 0 | BA7: 0 | BB7: 0 | BC7: 0 | BD7: 0 | BE7: 0
A8: 2021-09 | B8: =SUM(C8:XFD8) -> 3029.9259 | D8: 625.83598 | E8: 449.47874 | F8: 99.545925 | G8: 271.95747 | H8: 0 | I8: 147.29564 | J8: 119.86309 | K8: 310.56331 | L8: 55.195089 | M8: 85.387437 | N8: 0 | O8: 25.995585 | P8: 0 | Q8: 87.280878 | R8: 87.613728 | S8: 22.368471 | T8: 17.848368 | U8: 106.71266 | V8: 38.863566 | W8: 99.448923 | X8: 235.63878 | Y8: 0 | Z8: 0 | AA8: 0 | AB8: 9.141963 | AC8: 0 | AD8: 0 | AE8: 0 | AF8: 0 | AG8: 0 | AH8: 0 | AI8: 0 | AJ8: 45.000369 | AK8: 46.631334 | AL8: 0 | AM8: 0 | AN8: 0 | AO8: 0 | AP8: 0 | AQ8: 0 | AR8: 0 | AS8: 42.258636 | AT8: 0 | AU8: 0 | AV8: 0 | AW8: 0 | AX8: 0 | AY8: 0 | AZ8: 0 | BA8: 0 | BB8: 0 | BC8: 0 | BD8: 0 | BE8: 0
A9: 2021-10 | B9: =SUM(C9:XFD9) -> 1863.0337 | D9: 374.42582 | E9: 277.58834 | F9: 179.47938 | G9: 79.888755 | H9: 0 | I9: 98.227839 | J9: 44.546742 | K9: 113.15949 | L9: 0 | M9: 0 | N9: 0 | O9: 129.16672 | P9: 209.37216 | Q9: 0 | R9: 0 | S9: 51.679242 | T9: 33.727215 | U9: 0 | V9: 52.131918 | W9: 0 | X9: 40.999512 | Y9: 0 | Z9: 0 | AA9: 0 | AB9: 20.888715 | AC9: 0 | AD9: 40.934844 | AE9: 0 | AF9: 0 | AG9: 0 | AH9: 0 | AI9: 0 | AJ9: 0 | AK9: 0 | AL9: 71.222292 | AM9: 0 | AN9: 0 | AO9: 0 | AP9: 0 | AQ9: 0 | AR9: 0 | AS9: 0 | AT9: 0 | AU9: 0 | AV9: 45.594744 | AW9: 0 | AX9: 0 | AY9: 0 | AZ9: 0 | BA9: 0 | BB9: 0 | BC9: 0 | BD9: 0 | BE9: 0
A10: 2021-11 | B10: =SUM(C10:XFD10) -> 2139.3772 | D10: 593.30798 | E10: 633.83865 | F10: 108.8391 | G10: 0 | H10: 0 | I10: 82.892964 | J10: 45.074547 | K10: 74.173245 | L10: 46.490586 | M10: 25.411671 | N10: 0 | O10: 44.929995 | P10: 50.245134 | Q10: 39.486471 | R10: 0 | S10: 21.833058 | T10: 0 | U10: 71.721567 | V10: 113.27932 | W10: 0 | X10: 8.649345 | Y10: 64.588116 | Z10: 0 | AA10: 0 | AB10: 0 | AC10: 114.61547 | AD10: 0 | AE10: 0 | AF10: 0 | AG10: 0 | AH10: 0 | AI10: 0 | AJ10: 0 | AK10: 0 | AL10: 0 | AM10: 0 | AN10: 0 | AO10: 0 | AP10: 0 | AQ10: 0 | AR10: 0 | AS10: 0 | AT10: 0 | AU10: 0 | AV10: 0 | AW10: 0 | AX10: 0 | AY10: 0 | AZ10: 0 | BA10: 0 | BB10: 0 | BC10: 0 | BD10: 0 | BE10: 0
A11: 2021-12 | B11: =SUM(C11:XFD11) -> 2560.7073 | D11: 821.14761 | E11: 420.47799 | F11: 84.775944 | G11: 288.81014 | H11: 0 | I11: 67.298466 | J11: 89.201898 | K11: 38.000058 | L11: 22.621437 | M11: 17.833152 | N11: 0 | O11: 0 | P11: 40.000011 | Q11: 85.834407 | R11: 85.198188 | S11: 155.5817 | T11: 0 | U11: 0 | V11: 6.374553 | W11: 0 | X11: 0 | Y11: 135.1818 | Z11: 0 | AA11: 0 | AB11: 0 | AC11: 0 | AD11: 0 | AE11: 0 | AF11: 0 | AG11: 0 | AH11: 132.05206 | AI11: 0 | AJ11: 0 | AK11: 42.449787 | AL11: 0 | AM11: 0 | AN11: 25.540056 | AO11: 0 | AP11: 0 | AQ11: 0 | AR11: 0 | AS11: 0 | AT11: 0 | AU11: 0 | AV11: 0 | AW11: 0 | AX11: 0 | AY11: 0 | AZ11: 0 | BA11: 0 | BB11: 0 | BC11: 0 | BD11: 0 | BE11: 2.328048
A12: 2022-01 | B12: =SUM(C12:XFD12) -> 1839.9396 | D12: 406.11124 | E12: 317.2536 | F12: 179.15889 | G12: 179.60681 | H12: 0 | I12: 11.553699 | J12: 191.2927 | K12: 101.88253 | L12: 91.908444 | M12: 0 | N12: 0 | O12: 13.00017 | P12: 116.08572 | Q12: 0 | R12: 0 | S12: 29.01501 | T12: 73.723422 | U12: 12.234615 | V12: 0 | W12: 49.345488 | X12: 30.000246 | Y12: 4.767363 | Z12: 0 | AA12: 0 | AB12: 32.9997 | AC12: 0 | AD12: 0 | AE12: 0 | AF12: 0 | AG12: 0 | AH12: 0 | AI12: 0 | AJ12: 0 | AK12: 0 | AL12: 0 | AM12: 0 | AN12: 0 | AO12: 0 | AP12: 0 | AQ12: 0 | AR12: 0 | AS12: 0 | AT12: 0 | AU12: 0 | AV12: 0 | AW12: 0 | AX12: 0 | AY12: 0 | AZ12: 0 | BA12: 0 | BB12: 0 | BC12: 0 | BD12: 0 | BE12: 0
A13: 2022-02 | B13: =SUM(C13:XFD13) -> 1501.2775 | D13: 211.08681 | E13: 469.26524 | F13: 191.84238 | G13: 129.9998 | H13: 0 | I13: 117.11185 | J13: 47.504352 | K13: 0 | L13: 19.99953 | M13: 40.164534 | N13: 0 | O13: 0 | P13: 80.996109 | Q13: 0 | R13: 40.979541 | S13: 3.500631 | T13: 0 | U13: 0 | V13: 2.473551 | W13: 0 | X13: 0 | Y13: 42.660909 | Z13: 0 | AA13: 0 | AB13: 0 | AC13: 0 | AD13: 26.469183 | AE13: 0 | AF13: 0 | AG13: 0 | AH13: 0 | AI13: 0 | AJ13: 0 | AK13: 19.458411 | AL13: 31.417236 | AM13: 0 | AN13: 0 | AO13: 0 | AP13: 26.347455 | AQ13: 0 | AR13: 0 | AS13: 0 | AT13: 0 | AU13: 0 | AV13: 0 | AW13: 0 | AX13: 0 | AY13: 0 | AZ13: 0 | BA13: 0 | BB13: 0 | BC13: 0 | BD13: 0 | BE13: 0
... A62: 2026-03 | B62: =SUM(C62:XFD62) -> 831.20063 | D62: 315.70727 | E62: 113.05868 | F62: 148.52147 | G62: 155.41432 | H62: 0 | I62: 26.999841 | J62: 29.607483 | K62: 0 | L62: 32.9997 | M62: 0 | N62: 0 | O62: 0 | P62: 0 | Q62: 0 | R62: 0 | S62: 8.89185 | T62: 0 | U62: 0 | V62: 0 | W62: 0 | X62: 0 | Y62: 0 | Z62: 0 | AA62: 0 | AB62: 0 | AC62: 0 | AD62: 0 | AE62: 0 | AF62: 0 | AG62: 0 | AH62: 0 | AI62: 0 | AJ62: 0 | AK62: 0 | AL62: 0 | AM62: 0 | AN62: 0 | AO62: 0 | AP62: 0 | AQ62: 0 | AR62: 0 | AS62: 0 | AT62: 0 | AU62: 0 | AV62: 0 | AW62: 0 | AX62: 0 | AY62: 0 | AZ62: 0 | BA62: 0 | BB62: 0 | BC62: 0 | BD62: 0 | BE62: 0
A63: 2026-04 | B63: =SUM(C63:XFD63) -> 0
B64: =SUM(C64:XFD64) -> 0

Sheet Singapore Strait exports
A1: date | B1: Total | C1: ad-hoc | D1: Hong Kong | E1: China | F1: South Korea | G1: Taiwan | H1: Japan | I1: Australia | J1: Sri Lanka | K1: Unknown | L1: Philippines | M1: Thailand | N1: Malaysia | O1: Papua New Guinea | P1: Vietnam | Q1: United Arab Emirates | R1: Qatar | S1: Indonesia | T1: United States | U1: South Africa | V1: Cambodia | W1: Guam | X1: New Zealand | Y1: Brunei | Z1: New Caledonia | AA1: Saudi Arabia | AB1: Pakistan | AC1: Bangladesh | AD1: India | AE1: Mozambique | AF1: Kuwait | AG1: United States Virgin Islands | AH1: Italy | AI1: Mauritius | AJ1: Madagascar | AK1: Netherlands | AL1: Kenya | AM1: Micronesia | AN1: Guatemala | AO1: Nicaragua | AP1: Togo | AQ1: Panama | AR1: Maldives | AS1: Reunion
A2: 2021-04 | B2: =SUM(C2:AH2) -> 1062.3174 | D2: 387.23674 | E2: 419.04674 | F2: 42.988053 | G2: 25.826307 | H2: 12.637839 | I2: 36.612549 | J2: 11.286468 | K2: 1.03659 | L2: 0 | M2: 0 | N2: 6.577116 | O2: 0 | P2: 10.75581 | Q2: 0 | R2: 0 | S2: 0 | T2: 0 | U2: 0 | V2: 19.492647 | W2: 0 | X2: 0 | Y2: 0 | Z2: 29.563737 | AA2: 0 | AB2: 0 | AC2: 0 | AD2: 0 | AE2: 0 | AF2: 59.25681 | AG2: 0 | AH2: 0 | AI2: 0 | AJ2: 0 | AK2: 0 | AL2: 0 | AM2: 0 | AN2: 0 | AO2: 0 | AP2: 0 | AQ2: 0 | AR2: 0 | AS2: 0
A3: 2021-05 | B3: =SUM(C3:AH3) -> 1554.7928 | D3: 253.16666 | E3: 749.18924 | F3: 189.69407 | G3: 80.913933 | H3: 73.86417 | I3: 58.88592 | J3: 44.166342 | K3: 12.824235 | L3: 0 | M3: 39.294369 | N3: 16.700511 | O3: 0 | P3: 6.995556 | Q3: 0 | R3: 0 | S3: 0 | T3: 0 | U3: 24.708882 | V3: 0 | W3: 0 | X3: 0 | Y3: 0 | Z3: 4.388865 | AA3: 0 | AB3: 0 | AC3: 0 | AD3: 0 | AE3: 0 | AF3: 0 | AG3: 0 | AH3: 0 | AI3: 0 | AJ3: 0 | AK3: 0 | AL3: 0 | AM3: 0 | AN3: 0 | AO3: 0 | AP3: 0 | AQ3: 0 | AR3: 0 | AS3: 0
A4: 2021-06 | B4: =SUM(C4:AH4) -> 1207.7443 | D4: 427.38416 | E4: 418.76524 | F4: 69.266085 | G4: 48.999324 | H4: 0 | I4: 52.203243 | J4: 13.51371 | K4: 52.097682 | L4: 49.437735 | M4: 0 | N4: 0 | O4: 0 | P4: 0 | Q4: 0 | R4: 49.187622 | S4: 23.364168 | T4: 0 | U4: 0 | V4: 0 | W4: 0 | X4: 0 | Y4: 0 | Z4: 3.525357 | AA4: 0 | AB4: 0 | AC4: 0 | AD4: 0 | AE4: 0 | AF4: 0 | AG4: 0 | AH4: 0 | AI4: 0 | AJ4: 0 | AK4: 0 | AL4: 0 | AM4: 0 | AN4: 0 | AO4: 0 | AP4: 0 | AQ4: 0 | AR4: 0 | AS4: 0
A5: 2021-07 | B5: =SUM(C5:AH5) -> 1561.4469 | D5: 489.45878 | E5: 291.29606 | F5: 110.14862 | G5: 150.0231 | H5: 41.91057 | I5: 16.526478 | J5: 39.555894 | K5: 49.419666 | L5: 99.178839 | M5: 31.892736 | N5: 0 | O5: 0 | P5: 0 | Q5: 0 | R5: 52.436238 | S5: 0 | T5: 0 | U5: 45.458751 | V5: 0 | W5: 0 | X5: 0 | Y5: 0 | Z5: 0 | AA5: 113.5979 | AB5: 30.543267 | AC5: 0 | AD5: 0 | AE5: 0 | AF5: 0 | AG5: 0 | AH5: 0 | AI5: 0 | AJ5: 0 | AK5: 0 | AL5: 0 | AM5: 0 | AN5: 0 | AO5: 0 | AP5: 0 | AQ5: 0 | AR5: 0 | AS5: 0
A6: 2021-08 | B6: =SUM(C6:AH6) -> 1191.118 | D6: 438.60786 | E6: 363.86591 | F6: 122.66949 | G6: 68.183847 | H6: 0 | I6: 47.401644 | J6: 0 | K6: 5.084997 | L6: 62.382747 | M6: 0 | N6: 10.123395 | O6: 0 | P6: 9.052569 | Q6: 0 | R6: 0 | S6: 0 | T6: 0 | U6: 0 | V6: 0 | W6: 0 | X6: 0 | Y6: 0 | Z6: 2.725566 | AA6: 0 | AB6: 61.019964 | AC6: 0 | AD6: 0 | AE6: 0 | AF6: 0 | AG6: 0 | AH6: 0 | AI6: 0 | AJ6: 0 | AK6: 0 | AL6: 0 | AM6: 0 | AN6: 0 | AO6: 0 | AP6: 0 | AQ6: 0 | AR6: 0 | AS6: 0
A7: 2021-09 | B7: =SUM(C7:AH7) -> 960.99881 | D7: 522.1028 | E7: 107.77778 | F7: 155.90314 | G7: 91.583202 | H7: 0 | I7: 19.224465 | J7: 0 | K7: 13.28547 | L7: 0 | M7: 0 | N7: 10.123395 | O7: 0 | P7: 0 | Q7: 0 | R7: 0 | S7: 0 | T7: 0 | U7: 0 | V7: 0 | W7: 0 | X7: 6.920427 | Y7: 0 | Z7: 3.540573 | AA7: 30.537561 | AB7: 0 | AC7: 0 | AD7: 0 | AE7: 0 | AF7: 0 | AG7: 0 | AH7: 0 | AI7: 0 | AJ7: 0 | AK7: 0 | AL7: 0 | AM7: 0 | AN7: 0 | AO7: 0 | AP7: 0 | AQ7: 0 | AR7: 0 | AS7: 0
A8: 2021-10 | B8: =SUM(C8:AH8) -> 891.78408 | D8: 370.89 | E8: 360.75234 | F8: 54.295443 | G8: 48.16815 | H8: 0 | I8: 0 | J8: 0 | K8: 0 | L8: 0 | M8: 0 | N8: 8.222346 | O8: 0 | P8: 0 | Q8: 0 | R8: 0 | S8: 0 | T8: 0 | U8: 0 | V8: 0 | W8: 0 | X8: 0 | Y8: 0 | Z8: 0 | AA8: 0 | AB8: 0 | AC8: 0 | AD8: 0 | AE8: 49.455804 | AF8: 0 | AG8: 0 | AH8: 0 | AI8: 0 | AJ8: 0 | AK8: 0 | AL8: 0 | AM8: 0 | AN8: 0 | AO8: 0 | AP8: 12.283116 | AQ8: 0 | AR8: 0 | AS8: 0
A9: 2021-11 | B9: =SUM(C9:AH9) -> 1088.8398 | D9: 299.55834 | E9: 334.99355 | F9: 84.983262 | G9: 103.49162 | H9: 146.90477 | I9: 0 | J9: 0 | K9: 0 | L9: 34.914063 | M9: 0 | N9: 2.466894 | O9: 2.476404 | P9: 0 | Q9: 0 | R9: 46.490586 | S9: 6.944202 | T9: 0 | U9: 0 | V9: 0 | W9: 0 | X9: 0 | Y9: 0 | Z9: 5.824875 | AA9: 0 | AB9: 0 | AC9: 8.499087 | AD9: 11.292174 | AE9: 0 | AF9: 0 | AG9: 0 | AH9: 0 | AI9: 0 | AJ9: 0 | AK9: 0 | AL9: 0 | AM9: 0 | AN9: 0 | AO9: 0 | AP9: 0 | AQ9: 0 | AR9: 0 | AS9: 0
A10: 2021-12 | B10: =SUM(C10:AH10) -> 746.46272 | D10: 400.84745 | E10: 45.31515 | F10: 23.915748 | G10: 94.420035 | H10: 66.076431 | I10: 0 | J10: 0 | K10: 60.042336 | L10: 0 | M10: 0 | N10: 0 | O10: 9.8904 | P10: 0 | Q10: 0 | R10: 45.955173 | S10: 0 | T10: 0 | U10: 0 | V10: 0 | W10: 0 | X10: 0 | Y10: 0 | Z10: 0 | AA10: 0 | AB10: 0 | AC10: 0 | AD10: 0 | AE10: 0 | AF10: 0 | AG10: 0 | AH10: 0 | AI10: 0 | AJ10: 0 | AK10: 0 | AL10: 0 | AM10: 0 | AN10: 0 | AO10: 0 | AP10: 0 | AQ10: 0 | AR10: 0 | AS10: 0
A11: 2022-01 | B11: =SUM(C11:AH11) -> 655.1924 | D11: 102.89154 | E11: 162.92057 | F11: 111.49429 | G11: 84.984213 | H11: 136.15087 | I11: 0 | J11: 0 | K11: 0 | L11: 0 | M11: 0 | N11: 4.062672 | O11: 31.664496 | P11: 0 | Q11: 0 | R11: 0 | S11: 0 | T11: 0 | U11: 0 | V11: 0 | W11: 0 | X11: 0 | Y11: 0 | Z11: 6.90426 | AA11: 0 | AB11: 0 | AC11: 14.119497 | AD11: 0 | AE11: 0 | AF11: 0 | AG11: 0 | AH11: 0 | AI11: 0 | AJ11: 0 | AK11: 0 | AL11: 0 | AM11: 0 | AN11: 0 | AO11: 0 | AP11: 0 | AQ11: 0 | AR11: 0 | AS11: 0
A12: 2022-02 | B12: =SUM(C12:AH12) -> 852.34611 | D12: 486.83021 | E12: 96.175581 | F12: 34.37865 | G12: 107.78349 | H12: 0 | I12: 0 | J12: 0 | K12: 6.655098 | L12: 44.878641 | M12: 0 | N12: 3.999906 | O12: 0 | P12: 53.352051 | Q12: 0 | R12: 0 | S12: 0 | T12: 0 | U12: 0 | V12: 18.292485 | W12: 0 | X12: 0 | Y12: 0 | Z12: 0 | AA12: 0 | AB12: 0 | AC12: 0 | AD12: 0 | AE12: 0 | AF12: 0 | AG12: 0 | AH12: 0 | AI12: 0 | AJ12: 0 | AK12: 0 | AL12: 0 | AM12: 0 | AN12: 0 | AO12: 0 | AP12: 0 | AQ12: 0 | AR12: 0 | AS12: 0
A13: 2022-03 | B13: =SUM(C13:AH13) -> 942.08438 | D13: 291.97982 | E13: 216.56743 | F13: 118.37858 | G13: 69.644583 | H13: 87.345546 | I13: 0 | J13: 26.290395 | K13: 0 | L13: 15.000123 | M13: 0 | N13: 0 | O13: 0 | P13: 9.420606 | Q13: 0 | R13: 0 | S13: 0 | T13: 0 | U13: 0 | V13: 0 | W13: 0 | X13: 0 | Y13: 0 | Z13: 4.500132 | AA13: 0 | AB13: 0 | AC13: 0 | AD13: 66.736425 | AE13: 36.220737 | AF13: 0 | AG13: 0 | AH13: 0 | AI13: 0 | AJ13: 0 | AK13: 0 | AL13: 0 | AM13: 0 | AN13: 0 | AO13: 0 | AP13: 0 | AQ13: 0 | AR13: 0 | AS13: 0
... A62: 2026-04 | B62: =SUM(C62:AH62) -> 334.84425 | D62: 123.12312 | E62: 30.000246 | F62: 0 | G62: 0 | H62: 53.780952 | I62: 44.999418 | J62: 12.860373 | K62: 60.904893 | L62: 0 | M62: 9.175248 | N62: 0 | O62: 0 | P62: 0 | Q62: 0 | R62: 0 | S62: 0 | T62: 0 | U62: 0 | V62: 0 | W62: 0 | X62: 0 | Y62: 0 | Z62: 0 | AA62: 0 | AB62: 0 | AC62: 0 | AD62: 0 | AE62: 0 | AF62: 0 | AG62: 0 | AH62: 0 | AI62: 0 | AJ62: 0 | AK62: 0 | AL62: 0 | AM62: 0 | AN62: 0 | AO62: 0 | AP62: 0 | AQ62: 0 | AR62: 0 | AS62: 0

Sheet Bunker Sales
A1: BUNKER SALES (in '000 tonnes)
B3: Total | C3: MDO | D3: Bio-blended MDO | E3: MGO | F3: Bio-blended MGO | G3: LSMGO | H3: Bio-blended LSMGO | I3: MFO | J3: Bio-blended MFO | K3: LSFO | L3: Bio-blended LSFO | M3: ULSFO | N3: Bio-blended ULSFO | O3: B100 | P3: LNG | Q3: Methanol | R3: Ammonia
A5: 2013 | B5: 42682.18 | C5: 2.03 | D5: 0 | E5: 1182.93 | F5: 0 | G5: 190.9 | H5: 0 | I5: 40748.38 | J5: 0 | K5: 557.94 | L5: 0 | M5: 0 | N5: 0 | O5: 0 | P5: 0 | Q5: 0 | R5: 0
A6: 2014 | B6: 42416.75 | C6: 1.9 | D6: 0 | E6: 1022.3 | F6: 0 | G6: 287.94 | H6: 0 | I6: 40685.49 | J6: 0 | K6: 419.12 | L6: 0 | M6: 0 | N6: 0 | O6: 0 | P6: 0 | Q6: 0 | R6: 0
A7: 2015 | B7: 45155.54 | C7: 1.51 | D7: 0 | E7: 936.17 | F7: 0 | G7: 784.62 | H7: 0 | I7: 43409.04 | J7: 0 | K7: 24.2 | L7: 0 | M7: 0 | N7: 0 | O7: 0 | P7: 0 | Q7: 0 | R7: 0
A8: 2016 | B8: 48614.5 | C8: 0.46 | D8: 0 | E8: 853.44 | F8: 0 | G8: 1136.74 | H8: 0 | I8: 46496.22 | J8: 0 | K8: 127.63 | L8: 0 | M8: 0 | N8: 0 | O8: 0 | P8: 0 | Q8: 0 | R8: 0
A9: 2017 | B9: 50637.21 | C9: 0.07 | D9: 0 | E9: 736.09 | F9: 0 | G9: 1285.08 | H9: 0 | I9: 48469.47 | J9: 0 | K9: 145.69 | L9: 0 | M9: 0 | N9: 0 | O9: 0 | P9: 0.81 | Q9: 0 | R9: 0
A10: 2018 | B10: 49798.75 | C10: 0 | D10: 0 | E10: 746.83 | F10: 0 | G10: 1538.99 | H10: 0 | I10: 47180.96 | J10: 0 | K10: 331.98 | L10: 0 | M10: 0 | N10: 0 | O10: 0 | P10: 0 | Q10: 0 | R10: 0
A11: 2019 | B11: 47464.43 | C11: 0.76 | D11: 0 | E11: 792.04 | F11: 0 | G11: 3089.88 | H11: 0 | I11: 38101.72 | J11: 0 | K11: 5479.12 | L11: 0 | M11: 0 | N11: 0 | O11: 0 | P11: 0.9 | Q11: 0 | R11: 0
A12: 2020 | B12: 49833.03 | C12: 0.2 | D12: 0 | E12: 632.95 | F12: 0 | G12: 4062.17 | H12: 0 | I12: 10653.29 | J12: 0 | K12: 34083.66 | L12: 0 | M12: 400.77 | N12: 0 | O12: 0 | P12: 0 | Q12: 0 | R12: 0
A13: 2021 | B13: 50039.99 | C13: 0 | D13: 0 | E13: 360.28 | F13: 0 | G13: 3722.02 | H13: 0 | I13: 13034.92 | J13: 0 | K13: 32871.57 | L13: 2.01 | M13: 0 | N13: 0 | O13: 0 | P13: 49.19 | Q13: 0 | R13: 0 | S13: =K13/12 -> 2739.2975
A14: 2022 | B14: 47896.59 | C14: 0 | D14: 0 | E14: 140.48 | F14: 0 | G14: 3612.62 | H14: 0 | I14: 13992.07 | J14: 0 | K14: 29994.99 | L14: 140.13 | M14: 0 | N14: 0 | O14: 0 | P14: 16.3 | Q14: 0 | R14: 0 | S14: =K14/12 -> 2499.5825
A15: 2023 | B15: 51824.02 | C15: 0 | D15: 0 | E15: 223.51 | F15: 0 | G15: 3547.51 | H15: 0.2 | I15: 16716.67 | J15: 5.62 | K15: 30701.36 | L15: 518.01 | M15: 0 | N15: 0 | O15: 0 | P15: 110.85 | Q15: 0.3 | R15: 0 | S15: =K15/12 -> 2558.4467
A16: 2024 | B16: 54920.6 | C16: 1.12 | D16: 0.29 | E16: 96.72 | F16: 0.75 | G16: 3748.13 | H16: 9.98 | I16: 20147.86 | J16: 89.32 | K16: 29578.84 | L16: 779.85 | M16: 2.51 | N16: 2.64 | O16: 0 | P16: 460.95 | Q16: 1.63 | R16: 0.01 | S16: =K16/12 -> 2464.9033
A17: 2025 | B17: 56774.89 | C17: 0 | D17: 0 | E17: 32.66 | F17: 0 | G17: 4241.97 | H17: 9.68 | I17: 21712.03 | J17: 373.52 | K17: 28829.43 | L17: 969.19 | M17: 5.82 | N17: 0.71 | O17: 25.5 | P17: 571.35 | Q17: 3.01 | R17: 0
A19: 2025
A20: Jan | B20: 4487.91 | C20: 0 | D20: 0 | E20: 3.14 | F20: 0 | G20: 256.51 | H20: 0 | I20: 1655.35 | J20: 15.97 | K20: 2431.31 | L20: 91.96 | M20: 0.88 | N20: 0 | O20: 0 | P20: 32.8 | Q20: 0 | R20: 0
A21: Feb | B21: 4145.11 | C21: 0 | D21: 0 | E21: 8.93 | F21: 0 | G21: 305.71 | H21: 0 | I21: 1624.43 | J21: 22.09 | K21: 2065.1 | L21: 85.05 | M21: 0 | N21: 0 | O21: 3.77 | P21: 30.03 | Q21: 0 | R21: 0
A22: Mar | B22: 4469.16 | C22: 0 | D22: 0 | E22: 0.07 | F22: 0 | G22: 333.52 | H22: 0 | I22: 1618.59 | J22: 51.88 | K22: 2331.88 | L22: 93.71 | M22: 0.5 | N22: 0 | O22: 0 | P22: 39.03 | Q22: 0 | R22: 0
A23: Apr | B23: 4404.43 | C23: 0 | D23: 0 | E23: 0 | F23: 0 | G23: 314.74 | H23: 1.21 | I23: 1700.14 | J23: 33.29 | K23: 2236.49 | L23: 75.56 | M23: 0 | N23: 0.71 | O23: 0.3 | P23: 42 | Q23: 0 | R23: 0
A24: May | B24: 4878.14 | C24: 0 | D24: 0 | E24: 1.69 | F24: 0 | G24: 342.38 | H24: 2.28 | I24: 1892.76 | J24: 40.89 | K24: 2453.97 | L24: 96.08 | M24: 1.2 | N24: 0 | O24: 1.89 | P24: 45 | Q24: 0 | R24: 0
A25: Jun | B25: 4594.71 | C25: 0 | D25: 0 | E25: 4.49 | F25: 0 | G25: 362.02 | H25: 2.1 | I25: 1703.78 | J25: 38.75 | K25: 2311.01 | L25: 114.33 | M25: 1.9 | N25: 0 | O25: 1 | P25: 55.35 | Q25: 0 | R25: 0
A26: Jul | B26: 4918.02 | C26: 0 | D26: 0 | E26: 3.87 | F26: 0 | G26: 416.02 | H26: 1.75 | I26: 1949.42 | J26: 50.29 | K26: 2372.12 | L26: 80.45 | M26: 0 | N26: 0 | O26: 2.59 | P26: 41.53 | Q26: 0 | R26: 0
A27: Aug | B27: 4965.26 | C27: 0 | D27: 0 | E27: 1.75 | F27: 0 | G27: 368.56 | H27: 1.9 | I27: 1891.84 | J27: 34.69 | K27: 2500.97 | L27: 93.8 | M27: 0 | N27: 0 | O27: 4.79 | P27: 66.96 | Q27: 0 | R27: 0
A28: Sep | B28: 4765.09 | C28: 0 | D28: 0 | E28: 0.31 | F28: 0 | G28: 373.56 | H28: 0 | I28: 1872.95 | J28: 43.11 | K28: 2350.48 | L28: 71.7 | M28: 0 | N28: 0 | O28: 4.52 | P28: 48.45 | Q28: 0 | R28: 0
A29: Oct | B29: 4817.74 | C29: 0 | D29: 0 | E29: 2.25 | F29: 0 | G29: 392 | H29: 0 | I29: 1866.53 | J29: 11.14 | K29: 2433.38 | L29: 50.03 | M29: 0 | N29: 0 | O29: 1.8 | P29: 60.6 | Q29: 0 | R29: 0
A30: Nov | B30: 4820.68 | C30: 0 | D30: 0 | E30: 2.99 | F30: 0 | G30: 366.41 | H30: 0.45 | I30: 1818.67 | J30: 11.08 | K30: 2512.38 | L30: 45.81 | M30: 0 | N30: 0 | O30: 4.84 | P30: 55.04 | Q30: 3.01 | R30: 0
A31: Dec | B31: 5508.63 | C31: 0 | D31: 0 | E31: 3.18 | F31: 0 | G31: 410.55 | H31: 0 | I31: 2117.58 | J31: 20.35 | K31: 2830.32 | L31: 70.72 | M31: 1.36 | N31: 0 | O31: 0 | P31: 54.57 | Q31: 0 | R31: 0
B33: Total | C33: MDO | D33: Bio-blended MDO | E33: MGO | F33: Bio-blended MGO | G33: LSMGO | H33: Bio-blended LSMGO | I33: MFO | J33: Bio-blended MFO | K33: LSFO | L33: Bio-blended LSFO | M33: ULSFO | N33: Bio-blended ULSFO | O33: B100 | P33: LNG | Q33: Methanol | R33: Ammonia
A34: 2026
A35: Jan | B35: 5227.57 | C35: 0 | D35: 0 | E35: 2.01 | F35: 0 | G35: 402.06 | H35: 0 | I35: 2159.17 | J35: 14.26 | K35: 2561.23 | L35: 45.95 | M35: 0 | N35: 0 | O35: 0 | P35: 42.59 | Q35: 0.3 | R35: 0
A36: Feb* | B36: 4674.52 | C36: 0 | D36: 0 | E36: 3.57 | F36: 0 | G36: 370.53 | H36: 0 | I36: 1831.19 | J36: 13.96 | K36: 2309.95 | L36: 77.46 | M36: 1.56 | N36: 0 | O36: 1.3 | P36: 58.99 | Q36: 6.01 | R36: 0
A37: Mar
A38: Apr
A39: May
A40: Jun
A41: Jul
A42: Aug
A43: Sep
A44: Oct
...

Sheet Crude Imports
A1: date | B1: Total | C1: Ad-hoc | D1: Dar | E1: Ostra | F1: Vincent | G1: Atlanta | H1: Kraken | I1: Nile | J1: Doba Blend | K1: Pyrenees | L1: Van Gogh | M1: Yombo | N1: Meleck | O1: Escalante
A2: 2021-04 | B2: =SUM(C2:O2) -> 635.50281 | D2: 269.90835 | E2: 154.14829 | F2: 49.7658 | G2: 0 | H2: 70.520837 | I2: 0 | J2: 0 | K2: 91.15953 | L2: 0 | M2: 0 | N2: 0 | O2: 0
A3: 2021-05 | B3: =SUM(C3:O3) -> 630.24866 | D3: 238.54835 | E3: 0 | F3: 151.88589 | G3: 0 | H3: 81.160367 | I3: 0 | J3: 0 | K3: 43.132992 | L3: 115.52106 | M3: 0 | N3: 0 | O3: 0
A4: 2021-06 | B4: =SUM(C4:O4) -> 842.66521 | D4: 168.9408 | E4: 307.08519 | F4: 233.48752 | G4: 62.820242 | H4: 0 | I4: 0 | J4: 0 | K4: 43.132992 | L4: 27.198464 | M4: 0 | N4: 0 | O4: 0
A5: 2021-07 | B5: =SUM(C5:O5) -> 726.71019 | D5: 84.111104 | E5: 155.63802 | F5: 202.3933 | G5: 111.81474 | H5: 58.596552 | I5: 0 | J5: 0 | K5: 114.15648 | L5: 0 | M5: 0 | N5: 0 | O5: 0
A6: 2021-08 | B6: =SUM(C6:O6) -> 476.1475 | D6: 221.84064 | E6: 0 | F6: 86.155048 | G6: 0 | H6: 81.160367 | I6: 0 | J6: 0 | K6: 0 | L6: 86.991445 | M6: 0 | N6: 0 | O6: 0
A7: 2021-09 | B7: =SUM(C7:O7) -> 932.78357 | D7: 62.736128 | E7: 173.51478 | F7: 188.44174 | G7: 158.32746 | H7: 191.5389 | I7: 81.464768 | J7: 0 | K7: 0 | L7: 0 | M7: 76.759794 | N7: 0 | O7: 0
A8: 2021-10 | B8: =SUM(C8:O8) -> 651.78095 | D8: 219.52 | E8: 174.11441 | F8: 163.96391 | G8: 0 | H8: 50.094698 | I8: 0 | J8: 0 | K8: 0 | L8: 44.087926 | M8: 0 | N8: 0 | O8: 0
A9: 2021-11 | B9: =SUM(C9:O9) -> 712.43739 | D9: 85.557248 | E9: 159.85503 | F9: 82.407024 | G9: 83.862011 | H9: 103.30016 | I9: 0 | J9: 0 | K9: 88.635372 | L9: 108.82054 | M9: 0 | N9: 0 | O9: 0
A10: 2021-12 | B10: =SUM(C10:O10) -> 575.39534 | D10: 156.23821 | E10: 0 | F10: 214.51511 | G10: 0 | H10: 0 | I10: 69.970782 | J10: 0 | K10: 90.000162 | L10: 44.671077 | M10: 0 | N10: 0 | O10: 0
A11: 2022-01 | B11: =SUM(C11:O11) -> 556.29195 | D11: 57.492736 | E11: 168.63557 | F11: 186.31782 | G11: 83.86297 | H11: 10.30735 | I11: 0 | J11: 0 | K11: 0 | L11: 49.675503 | M11: 0 | N11: 0 | O11: 0
A12: 2022-02 | B12: =SUM(C12:O12) -> 804.84034 | D12: 220.3264 | E12: 149.73047 | F12: 58.213848 | G12: 0 | H12: 160.53966 | I12: 0 | J12: 0 | K12: 103.43514 | L12: 112.59482 | M12: 0 | N12: 0 | O12: 0
A13: 2022-03 | B13: =SUM(C13:O13) -> 516.70101 | D13: 73.971072 | E13: 91.693582 | F13: 185.26491 | G13: 0 | H13: 128.51458 | I13: 0 | J13: 0 | K13: 0 | L13: 37.256865 | M13: 0 | N13: 0 | O13: 0
... A62: 2026-04 | B62: =SUM(C62:O62) -> 193.02728 | D62: 85.471232 | E62: 69.015128 | F62: 0 | G62: 0 | H62: 0 | I62: 0 | J62: 38.540916 | K62: 0 | L62: 0 | M62: 0 | N62: 0 | O62: 0

Sheet Production
A1: Unit - Thousand Metric Tons (kmt)
A2: Product - Fuel oil
A3: BALANCE - Refinery output
A5: Time | B5: Jan2015 | C5: Feb2015 | D5: Mar2015 | E5: Apr2015 | F5: May2015 | G5: Jun2015 | H5: Jul2015 | I5: Aug2015 | J5: Sep2015 | K5: Oct2015 | L5: Nov2015 | M5: Dec2015 | N5: Jan2016 | O5: Feb2016 | P5: Mar2016 | Q5: Apr2016 | R5: May2016 | S5: Jun2016 | T5: Jul2016 | U5: Aug2016 | V5: Sep2016 | W5: Oct2016 | X5: Nov2016 | Y5: Dec2016 | Z5: Jan2017 | AA5: Feb2017 | AB5: Mar2017 | AC5: Apr2017 | AD5: May2017 | AE5: Jun2017 | AF5: Jul2017 | AG5: Aug2017 | AH5: Sep2017 | AI5: Oct2017 | AJ5: Nov2017 | AK5: Dec2017 | AL5: Jan2018 | AM5: Feb2018 | AN5: Mar2018 | AO5: Apr2018 | AP5: May2018 | AQ5: Jun2018 | AR5: Jul2018 | AS5: Aug2018 | AT5: Sep2018 | AU5: Oct2018 | AV5: Nov2018 | AW5: Dec2018 | AX5: Jan2019 | AY5: Feb2019 | AZ5: Mar2019 | BA5: Apr2019 | BB5: May2019 | BC5: Jun2019 | BD5: Jul2019 | BE5: Aug2019 | BF5: Sep2019 | BG5: Oct2019 | BH5: Nov2019 | BI5: Dec2019 | BJ5: Jan2020 | BK5: Feb2020 | BL5: Mar2020 | BM5: Apr2020 | BN5: May2020 | BO5: Jun2020 | BP5: Jul2020 | BQ5: Aug2020 | BR5: Sep2020 | BS5: Oct2020 | BT5: Nov2020 | BU5: Dec2020 | BV5: Jan2021 | BW5: Feb2021 | BX5: Mar2021 | BY5: Apr2021 | BZ5: May2021 | CA5: Jun2021 | CB5: Jul2021 | CC5: Aug2021 | CD5: Sep2021 | CE5: Oct2021 | CF5: Nov2021 | CG5: Dec2021 | CH5: Jan2022 | CI5: Feb2022 | CJ5: Mar2022 | CK5: Apr2022 | CL5: May2022 | CM5: Jun2022 | CN5: Jul2022 | CO5: Aug2022 | CP5: Sep2022 | CQ5: Oct2022 | CR5: Nov2022 | CS5: Dec2022 | CT5: Jan2023 | CU5: Feb2023 | CV5: Mar2023 | CW5: Apr2023 | CX5: May2023 | CY5: Jun2023 | CZ5: Jul2023 | DA5: Aug2023 | DB5: Sep2023 | DC5: Oct2023 | DD5: Nov2023 | DE5: Dec2023 | DF5: Jan2024 | DG5: Feb2024 | DH5: Mar2024 | DI5: Apr2024 | DJ5: May2024 | DK5: Jun2024 | DL5: Jul2024 | DM5: Aug2024 | DN5: Sep2024 | DO5: Oct2024 | DP5: Nov2024 | DQ5: Dec2024 | DR5: Jan2025 | DS5: Feb2025 | DT5: Mar2025 | DU5: Apr2025 | DV5: May2025 | DW5: Jun2025 | DX5: Jul2025 | DY5: Aug2025 | DZ5: Sep2025 | EA5: Oct2025 | EB5: Nov2025 | EC5: Dec2025 | ED5: Jan2026
A6: Country
A7: Indonesia | B7: - | C7: - | D7: - | E7: - | F7: - | G7: - | H7: - | I7: - | J7: - | K7: - | L7: - | M7: - | N7: 143 | O7: 167 | P7: 154 | Q7: 205 | R7: 181 | S7: 106 | T7: 175 | U7: 175 | V7: 160 | W7: - | X7: - | Y7: - | Z7: 156 | AA7: 141 | AB7: 149 | AC7: 264 | AD7: 150 | AE7: 82 | AF7: 107 | AG7: 45 | AH7: 103 | AI7: 181 | AJ7: 87 | AK7: 198 | AL7: 157 | AM7: 130 | AN7: 117 | AO7: 185 | AP7: 257 | AQ7: 170 | AR7: 192 | AS7: 164 | AT7: 176 | AU7: 149 | AV7: 146 | AW7: 154 | AX7: 162 | AY7: 146 | AZ7: 156 | BA7: 163 | BB7: 163 | BC7: 178 | BD7: 58 | BE7: 51 | BF7: 61 | BG7: 240 | BH7: 111 | BI7: 104 | BJ7: 100 | BK7: 100 | BL7: 100 | BM7: 100 | BN7: 100 | BO7: 100 | BP7: 156 | BQ7: 173 | BR7: 95 | BS7: 139 | BT7: 112 | BU7: 92 | BV7: 176 | BW7: 158 | BX7: 133 | BY7: 111 | BZ7: 125 | CA7: 132 | CB7: 100 | CC7: 23 | CD7: 85 | CE7: 247 | CF7: 205 | CG7: 268 | CH7: 256 | CI7: 287 | CJ7: 370 | CK7: 310 | CL7: 361 | CM7: 213 | CN7: 349 | CO7: 226 | CP7: 216 | CQ7: 284 | CR7: 267 | CS7: 233 | CT7: 256 | CU7: 287 | CV7: 269 | CW7: 265 | CX7: 317 | CY7: 260 | CZ7: 267 | DA7: 418 | DB7: 380 | DC7: 397 | DD7: 235 | DE7: 400 | DF7: 365 | DG7: 290 | DH7: 268 | DI7: 240 | DJ7: 268 | DK7: 260 | DL7: 248 | DM7: 268 | DN7: 297 | DO7: 328 | DP7: 282 | DQ7: 271 | DR7: 241 | DS7: 272 | DT7: 348 | DU7: 273 | DV7: 288 | DW7: 242 | DX7: 296 | DY7: 291 | DZ7: 269 | EA7: 251 | EB7: 246 | EC7: 216 | ED7: 193
A8: Malaysia | B8: - | C8: - | D8: - | E8: - | F8: - | G8: 202 | H8: 187 | I8: 207 | J8: - | K8: - | L8: 215 | M8: 236 | N8: 236 | O8: 243 | P8: 269 | Q8: 210 | R8: 215 | S8: 255 | T8: 232 | U8: 232 | V8: 247 | W8: 309 | X8: 248 | Y8: 312 | Z8: 303 | AA8: 277 | AB8: 298 | AC8: 225 | AD8: 268 | AE8: 270 | AF8: 260 | AG8: 253 | AH8: 259 | AI8: 298 | AJ8: 208 | AK8: 265 | AL8: 305 | AM8: 270 | AN8: 250 | AO8: 164 | AP8: 183 | AQ8: 205 | AR8: 214 | AS8: 234 | AT8: 234 | AU8: 255 | AV8: 250 | AW8: 265 | AX8: 289 | AY8: 243 | AZ8: 243 | BA8: 160 | BB8: 160 | BC8: 205 | BD8: 214 | BE8: 221 | BF8: 235 | BG8: 257 | BH8: 228 | BI8: 226 | BJ8: 277 | BK8: 275 | BL8: 275 | BM8: 93 | BN8: 134 | BO8: 134 | BP8: 141 | BQ8: 143 | BR8: 148 | BS8: 157 | BT8: 153 | BU8: 160 | BV8: 165 | BW8: 190 | BX8: 167 | BY8: 170 | BZ8: 160 | CA8: 179 | CB8: 189 | CC8: 189 | CD8: 196 | CE8: 183 | CF8: 150 | CG8: 179 | CH8: 169 | CI8: 172 | CJ8: 175 | CK8: 169 | CL8: 127 | CM8: 150 | CN8: 172 | CO8: 171 | CP8: 157 | CQ8: 176 | CR8: 172 | CS8: 181 | CT8: 183 | CU8: 110 | CV8: 145 | CW8: 133 | CX8: 151 | CY8: 194 | CZ8: 153 | DA8: 210 | DB8: 195 | DC8: 162 | DD8: 146 | DE8: 154 | DF8: 153 | DG8: 132 | DH8: 172 | DI8: 167 | DJ8: 172 | DK8: 285 | DL8: 188 | DM8: 221 | DN8: 214 | DO8: 180 | DP8: 150 | DQ8: 151 | DR8: 197 | DS8: 172 | DT8: 225 | DU8: 209 | DV8: - | DW8: 255 | DX8: 216 | DY8: 203 | DZ8: 193 | EA8: 147 | EB8: 137 | EC8: 163 | ED8: -
A9: Singapore | B9: - | C9: - | D9: - | E9: - | F9: - | G9: - | H9: - | I9: - | J9: - | K9: - | L9: - | M9: - | N9: - | O9: - | P9: - | Q9: - | R9: - | S9: - | T9: - | U9: - | V9: - | W9: - | X9: - | Y9: - | Z9: - | AA9: - | AB9: - | AC9: - | AD9: - | AE9: - | AF9: - | AG9: - | AH9: - | AI9: - | AJ9: - | AK9: - | AL9: - | AM9: - | AN9: - | AO9: - | AP9: - | AQ9: - | AR9: - | AS9: - | AT9: - | AU9: - | AV9: - | AW9: - | AX9: - | AY9: - | AZ9: - | BA9: - | BB9: - | BC9: - | BD9: - | BE9: - | BF9: - | BG9: - | BH9: - | BI9: - | BJ9: - | BK9: - | BL9: - | BM9: - | BN9: - | BO9: - | BP9: - | BQ9: - | BR9: - | BS9: - | BT9: - | BU9: - | BV9: - | BW9: - | BX9: - | BY9: - | BZ9: - | CA9: - | CB9: - | CC9: - | CD9: - | CE9: - | CF9: - | CG9: - | CH9: - | CI9: - | CJ9: - | CK9: - | CL9: - | CM9: - | CN9: - | CO9: - | CP9: - | CQ9: - | CR9: - | CS9: - | CT9: 0 | CU9: 0 | CV9: 0 | CW9: 0 | CX9: 0 | CY9: 0 | CZ9: 0 | DA9: 0 | DB9: 0 | DC9: 0 | DD9: 0 | DE9: 0 | DF9: 0 | DG9: 0 | DH9: 0 | DI9: 0 | DJ9: 0 | DK9: 0 | DL9: 0 | DM9: 0 | DN9: 0 | DO9: 0 | DP9: 0 | DQ9: 0 | DR9: 0 | DS9: 0 | DT9: 0 | DU9: 0 | DV9: 0 | DW9: 0 | DX9: 0 | DY9: 0 | DZ9: 0 | EA9: 0 | EB9: 0 | EC9: 0 | ED9: 0
A11: Total | B11: =SUM(B7:B9) -> 0 | C11: =SUM(C7:C9) -> 0 | D11: =SUM(D7:D9) -> 0 | E11: =SUM(E7:E9) -> 0 | F11: =SUM(F7:F9) -> 0 | G11: =SUM(G7:G9) -> 202 | H11: =SUM(H7:H9) -> 187 | I11: =SUM(I7:I9) -> 207 | ... ED11: =SUM(ED7:ED9) -> 193
B13: =B11*0.65 -> 0 | C13: =C11*0.65 -> 0 | D13: =D11*0.65 -> 0 | E13: =E11*0.65 -> 0 | F13: =F11*0.65 -> 0 | G13: =G11*0.65 -> 131.3 | H13: =H11*0.65 -> 121.55 | I13: =I11*0.65 -> 134.55 | ... ED13: =ED11*0.65 -> 125.45
A16: 43101
A17: 43132
A18: 43160
A19: 43191
A20: 43221
A21: 43252
A22: 43282
A23: 43313
A24: 43344
A25: 43374
A26: 43405
A27: 43435
... A105: 45809

Sheet Storage onshore
A1: Bloomberg onshore storage
A2: Date | B2: Stock | D2: Daily | E2: Stock | I2: 43831 | J2: 43862 | K2: 43891 | L2: 43922 | M2: 43952 | N2: 43983 | O2: 44013 | P2: 44044 | Q2: 44075 | R2: 44105 | S2: 44136 | T2: 44166 | U2: 44197 | V2: 44228 | W2: 44256 | X2: 44287 | Y2: 44317 | Z2: 44348 | AA2: 44378 | AB2: 44409 | AC2: 44440 | AD2: 44470 | AE2: 44501 | AF2: 44531 | AG2: 44562 | AH2: 44593 | AI2: 44621 | AJ2: 44652 | AK2: 44682 | AL2: 44713 | AM2: 44743 | AN2: 44774 | AO2: 44805 | AP2: 44835 | AQ2: 44866 | AR2: 44896 | AS2: 44927 | AT2: 44958 | AU2: 44986 | AV2: 45017 | AW2: 45047 | AX2: 45078 | AY2: 45108 | AZ2: 45139 | BA2: 45170 | BB2: 45200 | BC2: 45231 | BD2: 45261 | BE2: 45292 | BF2: 45323 | BG2: 45352 | BH2: 45383 | BI2: 45413 | BJ2: 45444 | BK2: 45474 | BL2: 45505 | BM2: 45536 | BN2: 45566 | BO2: 45597 | BP2: 45627 | BQ2: 45658 | BR2: 45689 | BS2: 45717 | BT2: 45748 | BU2: 45778 | BV2: 45809 | BW2: 45839 | BX2: 45870 | BY2: 45901 | BZ2: 45931 | CA2: 45962
A3: 42739 | B3: 18604 | D3: 44123 | E3: =LOOKUP(D3,A:A,B:B) -> 24652 | H3: =G3=D3 -> FALSE | I3: =_xlfn.MAXIFS($B:$B,$A:$A,">="&I2,$A:$A,"<="&EOMONTH(I2,0)) -> 23555 | J3: =_xlfn.MAXIFS($B:$B,$A:$A,">="&J2,$A:$A,"<="&EOMONTH(J2,0)) -> 24971 | K3: =_xlfn.MAXIFS($B:$B,$A:$A,">="&K2,$A:$A,"<="&EOMONTH(K2,0)) -> 26118 | L3: =_xlfn.MAXIFS($B:$B,$A:$A,">="&L2,$A:$A,"<="&EOMONTH(L2,0)) -> 24541 | M3: =_xlfn.MAXIFS($B:$B,$A:$A,">="&M2,$A:$A,"<="&EOMONTH(M2,0)) -> 26172 | N3: =_xlfn.MAXIFS($B:$B,$A:$A,">="&N2,$A:$A,"<="&EOMONTH(N2,0)) -> 26630 | O3: =_xlfn.MAXIFS($B:$B,$A:$A,">="&O2,$A:$A,"<="&EOMONTH(O2,0)) -> 26666 | P3: =_xlfn.MAXIFS($B:$B,$A:$A,">="&P2,$A:$A,"<="&EOMONTH(P2,0)) -> 25485 | ... CA3: =_xlfn.MAXIFS($B:$B,$A:$A,">="&CA2,$A:$A,"<="&EOMONTH(CA2,0)) -> 25952
A4: 42746 | B4: 21978 | D4: 44124 | E4: =LOOKUP(D4,A:A,B:B) -> 24652 | H4: =G4=D4 -> FALSE
A5: 42753 | B5: 22007 | D5: 44125 | E5: =LOOKUP(D5,A:A,B:B) -> 24317 | G5: 44125 | H5: =G5=D5 -> TRUE
A6: 42760 | B6: 21827 | D6: 44126 | E6: =LOOKUP(D6,A:A,B:B) -> 24317 | G6: 44126 | H6: =G6=D6 -> TRUE
A7: 42767 | B7: 23821 | D7: 44127 | E7: =LOOKUP(D7,A:A,B:B) -> 24317 | G7: 44127 | H7: =G7=D7 -> TRUE
A8: 42774 | B8: 25766 | D8: 44130 | E8: =LOOKUP(D8,A:A,B:B) -> 24317 | G8: 44130 | H8: =G8=D8 -> TRUE
A9: 42781 | B9: 24060 | D9: 44131 | E9: =LOOKUP(D9,A:A,B:B) -> 24317 | G9: 44131 | H9: =G9=D9 -> TRUE
A10: 42788 | B10: 26647 | D10: 44132 | E10: =LOOKUP(D10,A:A,B:B) -> 23216 | G10: 44132 | H10: =G10=D10 -> TRUE
A11: 42795 | B11: 26460 | D11: 44133 | E11: =LOOKUP(D11,A:A,B:B) -> 23216 | G11: 44133 | H11: =G11=D11 -> TRUE
A12: 42802 | B12: 27734 | D12: 44134 | E12: =LOOKUP(D12,A:A,B:B) -> 23216 | G12: 44134 | H12: =G12=D12 -> TRUE
A13: 42809 | B13: 26929 | D13: 44137 | E13: =LOOKUP(D13,A:A,B:B) -> 23216 | G13: 44137 | H13: =G13=D13 -> TRUE
A14: 42816 | B14: 27072 | D14: 44138 | E14: =LOOKUP(D14,A:A,B:B) -> 23216 | G14: 44138 | H14: =G14=D14 -> TRUE
A15: 42823 | B15: 25414 | D15: 44139 | E15: =LOOKUP(D15,A:A,B:B) -> 23228 | G15: 44139 | H15: =G15=D15 -> TRUE
A16: 42830 | B16: 23565 | D16: 44140 | E16: =LOOKUP(D16,A:A,B:B) -> 23228 | G16: 44140 | H16: =G16=D16 -> TRUE
... A486: 46120 | B486: 21722 | D486: 44804 | E486: =LOOKUP(D486,A:A,B:B) -> 22667 | G486: 44804 | H486: =G486=D486 -> TRUE
D487: 44805 | E487: =LOOKUP(D487,A:A,B:B) -> 22667 | G487: 44805 | H487: =G487=D487 -> TRUE
D488: 44806 | E488: =LOOKUP(D488,A:A,B:B) -> 22667 | G488: 44806 | H488: =G488=D488 -> TRUE
D489: 44809 | E489: =LOOKUP(D489,A:A,B:B) -> 22667 | G489: 44809 | H489: =G489=D489 -> TRUE
D490: 44810 | E490: =LOOKUP(D490,A:A,B:B) -> 22667 | G490: 44810 | H490: =G490=D490 -> TRUE
D491: 44811 | E491: =LOOKUP(D491,A:A,B:B) -> 19938 | G491: 44811 | H491: =G491=D491 -> TRUE
D492: 44812 | E492: =LOOKUP(D492,A:A,B:B) -> 19938 | G492: 44812 | H492: =G492=D492 -> TRUE
D493: 44813 | E493: =LOOKUP(D493,A:A,B:B) -> 19938 | G493: 44813 | H493: =G493=D493 -> TRUE
D494: 44816 | E494: =LOOKUP(D494,A:A,B:B) -> 19938 | G494: 44816 | H494: =G494=D494 -> TRUE
D495: 44817 | E495: =LOOKUP(D495,A:A,B:B) -> 19938 | G495: 44817 | H495: =G495=D495 -> TRUE
D496: 44818 | E496: =LOOKUP(D496,A:A,B:B) -> 19419 | G496: 44818 | H496: =G496=D496 -> TRUE
D497: 44819 | E497: =LOOKUP(D497,A:A,B:B) -> 19419 | G497: 44819 | H497: =G497=D497 -> TRUE
D498: 44820 | E498: =LOOKUP(D498,A:A,B:B) -> 19419 | G498: 44820 | H498: =G498=D498 -> TRUE
... D532: 44868 | E532: =LOOKUP(D532,A:A,B:B) -> 18949 | G532: 44868 | H532: =G532=D532 -> TRUE
D533: 44869 | E533: =LOOKUP(D533,A:A,B:B) -> 18949 | G533: 44869 | H533: =G533=D533 -> TRUE | K533: SSGP599
D534: 44872 | E534: =LOOKUP(D534,A:A,B:B) -> 18949 | G534: 44872 | H534: =G534=D534 -> TRUE
D535: 44873 | E535: =LOOKUP(D535,A:A,B:B) -> 18949 | G535: 44873 | H535: =G535=D535 -> TRUE
D536: 44874 | E536: =LOOKUP(D536,A:A,B:B) -> 21471 | G536: 44874 | H536: =G536=D536 -> TRUE
D537: 44875 | E537: =LOOKUP(D537,A:A,B:B) -> 21471 | G537: 44875 | H537: =G537=D537 -> TRUE
D538: 44876 | E538: =LOOKUP(D538,A:A,B:B) -> 21471 | G538: 44876 | H538: =G538=D538 -> TRUE
D539: 44879 | E539: =LOOKUP(D539,A:A,B:B) -> 21471 | G539: 44879 | H539: =G539=D539 -> TRUE
D540: 44880 | E540: =LOOKUP(D540,A:A,B:B) -> 21471 | G540: 44880 | H540: =G540=D540 -> TRUE
D541: 44881 | E541: =LOOKUP(D541,A:A,B:B) -> 21168 | G541: 44881 | H541: =G541=D541 -> TRUE
D542: 44882 | E542: =LOOKUP(D542,A:A,B:B) -> 21168 | G542: 44882 | H542: =G542=D542 -> TRUE
...

Sheet Floating Storage
A1: Floating Storage | D1: Weekly
A2: date | B2: Total | D2: Date | E2: Stock | G2: Daily | H2: Stock | K2: 44105 | L2: 44136 | M2: 44166 | N2: 44197 | O2: 44228 | P2: 44256 | Q2: 44287 | R2: 44317 | S2: 44348 | T2: 44378 | U2: 44409 | V2: 44440 | W2: 44470 | X2: 44501 | Y2: 44531 | Z2: 44562 | AA2: 44593 | AB2: 44621 | AC2: 44652 | AD2: 44682 | AE2: 44713 | AF2: 44743 | AG2: 44774 | AH2: 44805 | AI2: 44835 | AJ2: 44866 | AK2: 44896 | AL2: 44927 | AM2: 44958 | AN2: 44986 | AO2: 45017 | AP2: 45047 | AQ2: 45078 | AR2: 45108 | AS2: 45139 | AT2: 45170 | AU2: 45200 | AV2: 45231 | AW2: 45261 | AX2: 45292 | AY2: 45323 | AZ2: 45352 | BA2: 45383 | BB2: 45413 | BC2: 45444 | BD2: 45474 | BE2: 45505 | BF2: 45536 | BG2: 45566 | BH2: 45597 | BI2: 45627 | BJ2: 45658 | BK2: 45689 | BL2: 45717 | BM2: 45748 | BN2: 45778 | BO2: 45809 | BP2: 45839 | BQ2: 45870 | BR2: 45901 | BS2: 45931
A3: 2021-01-03 | B3: 2058.608 | D3: 44199 | E3: 2058.608 | G3: 45396 | H3: =LOOKUP(G3,D:D,E:E) -> 2171.908 | K3: =_xlfn.MAXIFS($E:$E,$D:$D,">="&K2,$D:$D,"<="&EOMONTH(K2,0)) -> 0 | L3: =_xlfn.MAXIFS($E:$E,$D:$D,">="&L2,$D:$D,"<="&EOMONTH(L2,0)) -> 0 | M3: =_xlfn.MAXIFS($E:$E,$D:$D,">="&M2,$D:$D,"<="&EOMONTH(M2,0)) -> 0 | N3: =_xlfn.MAXIFS($E:$E,$D:$D,">="&N2,$D:$D,"<="&EOMONTH(N2,0)) -> 2058.608 | O3: =_xlfn.MAXIFS($E:$E,$D:$D,">="&O2,$D:$D,"<="&EOMONTH(O2,0)) -> 2318.567 | P3: =_xlfn.MAXIFS($E:$E,$D:$D,">="&P2,$D:$D,"<="&EOMONTH(P2,0)) -> 2472.659 | Q3: =_xlfn.MAXIFS($E:$E,$D:$D,">="&Q2,$D:$D,"<="&EOMONTH(Q2,0)) -> 2557.161 | R3: =_xlfn.MAXIFS($E:$E,$D:$D,">="&R2,$D:$D,"<="&EOMONTH(R2,0)) -> 2355.904 | ... BS3: =_xlfn.MAXIFS($E:$E,$D:$D,">="&BS2,$D:$D,"<="&EOMONTH(BS2,0)) -> 1537.274
A4: 2021-01-10 | B4: 2019.795 | D4: =D3+7 -> 44206 | E4: 2019.795 | G4: =G3+1 -> 45397 | H4: =LOOKUP(G4,D:D,E:E) -> 2171.908
A5: 2021-01-17 | B5: 1865.97 | D5: =D4+7 -> 44213 | E5: 1865.97 | G5: =G4+1 -> 45398 | H5: =LOOKUP(G5,D:D,E:E) -> 2171.908
A6: 2021-01-24 | B6: 1797.953 | D6: =D5+7 -> 44220 | E6: 1797.953 | G6: =G5+1 -> 45399 | H6: =LOOKUP(G6,D:D,E:E) -> 2171.908
A7: 2021-01-31 | B7: 2001.376 | D7: =D6+7 -> 44227 | E7: 2001.376 | G7: =G6+1 -> 45400 | H7: =LOOKUP(G7,D:D,E:E) -> 2171.908
A8: 2021-02-07 | B8: 2063.775 | D8: =D7+7 -> 44234 | E8: 2063.775 | G8: =G7+1 -> 45401 | H8: =LOOKUP(G8,D:D,E:E) -> 2171.908
A9: 2021-02-14 | B9: 1990.64 | D9: =D8+7 -> 44241 | E9: 1990.64 | G9: =G8+1 -> 45402 | H9: =LOOKUP(G9,D:D,E:E) -> 2171.908
A10: 2021-02-21 | B10: 2029.753 | D10: =D9+7 -> 44248 | E10: 2029.753 | G10: =G9+1 -> 45403 | H10: =LOOKUP(G10,D:D,E:E) -> 2071.498
A11: 2021-02-28 | B11: 2318.567 | D11: =D10+7 -> 44255 | E11: 2318.567 | G11: =G10+1 -> 45404 | H11: =LOOKUP(G11,D:D,E:E) -> 2071.498
A12: 2021-03-07 | B12: 2329.313 | D12: =D11+7 -> 44262 | E12: 2329.313 | G12: =G11+1 -> 45405 | H12: =LOOKUP(G12,D:D,E:E) -> 2071.498
A13: 2021-03-14 | B13: 2051.188 | D13: =D12+7 -> 44269 | E13: 2051.188 | G13: =G12+1 -> 45406 | H13: =LOOKUP(G13,D:D,E:E) -> 2071.498
A14: 2021-03-21 | B14: 2149.85 | D14: =D13+7 -> 44276 | E14: 2149.85 | G14: =G13+1 -> 45407 | H14: =LOOKUP(G14,D:D,E:E) -> 2071.498
A15: 2021-03-28 | B15: 2472.659 | D15: =D14+7 -> 44283 | E15: 2472.659 | G15: =G14+1 -> 45408 | H15: =LOOKUP(G15,D:D,E:E) -> 2071.498
... A279: 2026-04-16 | B279: 1241.753 | D279: =D278+7 -> 46131 | E279: 1241.753 | G279: =G278+1 -> 45672 | H279: =LOOKUP(G279,D:D,E:E) -> 1617.852
G280: =G279+1 -> 45673 | H280: =LOOKUP(G280,D:D,E:E) -> 1617.852
G281: =G280+1 -> 45674 | H281: =LOOKUP(G281,D:D,E:E) -> 1617.852
G282: =G281+1 -> 45675 | H282: =LOOKUP(G282,D:D,E:E) -> 1617.852
G283: =G282+1 -> 45676 | H283: =LOOKUP(G283,D:D,E:E) -> 1478.568
G284: =G283+1 -> 45677 | H284: =LOOKUP(G284,D:D,E:E) -> 1478.568
G285: =G284+1 -> 45678 | H285: =LOOKUP(G285,D:D,E:E) -> 1478.568
G286: =G285+1 -> 45679 | H286: =LOOKUP(G286,D:D,E:E) -> 1478.568
G287: =G286+1 -> 45680 | H287: =LOOKUP(G287,D:D,E:E) -> 1478.568
G288: =G287+1 -> 45681 | H288: =LOOKUP(G288,D:D,E:E) -> 1478.568
G289: =G288+1 -> 45682 | H289: =LOOKUP(G289,D:D,E:E) -> 1478.568
G290: =G289+1 -> 45683 | H290: =LOOKUP(G290,D:D,E:E) -> 1685.12
G291: =G290+1 -> 45684 | H291: =LOOKUP(G291,D:D,E:E) -> 1685.12
... G749: =G748+1 -> 46142 | H749: =LOOKUP(G749,D:D,E:E) -> 1241.753

Sheet Balance Forecast
B2: 44287 | C2: 44317 | D2: 44348 | E2: 44378 | F2: 44409 | G2: 44440 | H2: 44470 | I2: 44501 | J2: 44531 | K2: 44562 | L2: 44593 | M2: 44621 | N2: 44652 | O2: 44682 | P2: 44713 | Q2: 44743 | R2: 44774 | S2: 44805 | T2: 44835 | U2: 44866 | V2: 44896 | W2: 44927 | X2: 44958 | Y2: 44986 | Z2: 45017 | AA2: 45047 | AB2: 45078 | AC2: 45108 | AD2: 45139 | AE2: 45170 | AF2: 45200 | AG2: 45231 | AH2: 45261 | AI2: 45292 | AJ2: 45323 | AK2: 45352 | AL2: 45383 | AM2: 45413 | AN2: 45444 | AO2: 45474 | AP2: 45505 | AQ2: 45536 | AR2: 45566 | AS2: 45597 | AT2: 45627 | AU2: 45658 | AV2: 45689 | AW2: 45717 | AX2: 45748 | AY2: 45778 | AZ2: 45809 | BA2: 45839 | BB2: 45870 | BC2: 45901 | BD2: 45931 | BE2: 45962 | BF2: 45992 | BG2: 46023 | BH2: 46054 | BI2: 46082 | BJ2: 46113 | BK2: 46143 | BL2: 46174 | BM2: 46204 | BN2: 46235 | BO2: 46266 | BP2: 46296 | BQ2: 46327 | BR2: 46357
A3: On-shore storage (kbbl) | B3: ='Storage onshore'!X3 -> 24813 | C3: ='Storage onshore'!Y3 -> 27228 | D3: ='Storage onshore'!Z3 -> 26900 | E3: ='Storage onshore'!AA3 -> 24434 | F3: ='Storage onshore'!AB3 -> 22566 | G3: ='Storage onshore'!AC3 -> 24148 | H3: ='Storage onshore'!AD3 -> 21800 | I3: ='Storage onshore'!AE3 -> 22903 | ... BE3: ='Storage onshore'!CA3 -> 25952 | BF3: 26752 | BG3: 19938 | BH3: 22632 | BI3: 24509 | BJ3: =ROUND(BI3*(1-$E$25)+$E$24*$E$25+(F$35-$E$24)*$E$26, 0) -> 24361 | BK3: =ROUND(BJ3*(1-$E$25)+$E$24*$E$25+(G$35-$E$24)*$E$26, 0) -> 23430 | BL3: =ROUND(BK3*(1-$E$25)+$E$24*$E$25+(H$35-$E$24)*$E$26, 0) -> 23496 | BM3: =ROUND(BL3*(1-$E$25)+$E$24*$E$25+(I$35-$E$24)*$E$26, 0) -> 23132 | BN3: =ROUND(BM3*(1-$E$25)+$E$24*$E$25+(J$35-$E$24)*$E$26, 0) -> 23124 | BO3: =ROUND(BN3*(1-$E$25)+$E$24*$E$25+(K$35-$E$24)*$E$26, 0) -> 23145 | BP3: =ROUND(BO3*(1-$E$25)+$E$24*$E$25+(L$35-$E$24)*$E$26, 0) -> 22925 | BQ3: =ROUND(BP3*(1-$E$25)+$E$24*$E$25+(M$35-$E$24)*$E$26, 0) -> 22732 | BR3: =ROUND(BQ3*(1-$E$25)+$E$24*$E$25+(N$35-$E$24)*$E$26, 0) -> 25756
A4: On-shore storage (kt) | B4: =(B3/6.35)*'Bunker Sales'!F58 -> 2798.0756 | C4: =(C3/6.35)*'Bunker Sales'!F58 -> 3070.4068 | D4: =(D3/6.35)*'Bunker Sales'!F58 -> 3033.4194 | E4: =(E3/6.35)*'Bunker Sales'!F58 -> 2755.3371 | F4: =(F3/6.35)*'Bunker Sales'!F58 -> 2544.6893 | G4: =(G3/6.35)*'Bunker Sales'!F58 -> 2723.0859 | H4: =(H3/6.35)*'Bunker Sales'!F58 -> 2458.3101 | I4: =(I3/6.35)*'Bunker Sales'!F58 -> 2582.6916 | J4: =(J3/6.35)*'Bunker Sales'!F58 -> 2360.7671 | K4: =(K3/6.35)*'Bunker Sales'!F59 -> 2557.6511 | L4: =(L3/6.35)*'Bunker Sales'!F59 -> 2594.8619 | M4: =(M3/6.35)*'Bunker Sales'!F59 -> 2511.7291 | N4: =(N3/6.35)*'Bunker Sales'!F59 -> 2484.6276 | O4: =(O3/6.35)*'Bunker Sales'!F59 -> 2269.8589 | P4: =(P3/6.35)*'Bunker Sales'!F59 -> 2303.8433 | Q4: =(Q3/6.35)*'Bunker Sales'!F59 -> 2302.3377 | R4: =(R3/6.35)*'Bunker Sales'!F59 -> 2437.7377 | S4: =(S3/6.35)*'Bunker Sales'!F59 -> 2516.5687 | T4: =(T3/6.35)*'Bunker Sales'!F59 -> 2462.6883 | U4: =(U3/6.35)*'Bunker Sales'!F59 -> 2309.1131 | V4: =(V3/6.35)*'Bunker Sales'!F59 -> 2301.8 | W4: =(W3/6.35)*'Bunker Sales'!F60 -> 2187.7076 | X4: =(X3/6.35)*'Bunker Sales'!F60 -> 2321.8435 | Y4: =(Y3/6.35)*'Bunker Sales'!F60 -> 2363.5815 | Z4: =(Z3/6.35)*'Bunker Sales'!F60 -> 2434.5464 | AA4: =(AA3/6.35)*'Bunker Sales'!F60 -> 2114.4866 | AB4: =(AB3/6.35)*'Bunker Sales'!F60 -> 2179.1959 | AC4: =(AC3/6.35)*'Bunker Sales'!F60 -> 2145.6619 | AD4: =(AD3/6.35)*'Bunker Sales'!F60 -> 2350.5576 | AE4: =(AE3/6.35)*'Bunker Sales'!F60 -> 2241.2389 | AF4: =(AF3/6.35)*'Bunker Sales'!F60 -> 2003.322 | AG4: =(AG3/6.35)*'Bunker Sales'!F60 -> 2063.5191 | AH4: =(AH3/6.35)*'Bunker Sales'!F60 -> 2211.7044 | AI4: =(AI3/6.35)*'Bunker Sales'!F61 -> 2214.9441 | AJ4: =(AJ3/6.35)*'Bunker Sales'!F61 -> 2207.3843 | AK4: =(AK3/6.35)*'Bunker Sales'!F61 -> 2079.8117 | AL4: =(AL3/6.35)*'Bunker Sales'!F61 -> 2096.5378 | AM4: =(AM3/6.35)*'Bunker Sales'!F61 -> 1961.1219 | AN4: =(AN3/6.35)*'Bunker Sales'!F61 -> 2155.2212 | AO4: =(AO3/6.35)*'Bunker Sales'!F61 -> 1902.4385 | AP4: =(AP3/6.35)*'Bunker Sales'!F61 -> 1864.1667 | AQ4: =(AQ3/6.35)*'Bunker Sales'!F61 -> 1772.6924 | AR4: =(AR3/6.35)*'Bunker Sales'!F61 -> 1903.6669 | AS4: =(AS3/6.35)*'Bunker Sales'!F61 -> 1817.3901 | AT4: =(AT3/6.35)*'Bunker Sales'!F61 -> 2737.3304 | AU4: =(AU3/6.35)*'Bunker Sales'!F62 -> 2052.9697 | AV4: =(AV3/6.35)*'Bunker Sales'!F63 -> 1863.6201 | AW4: =(AW3/6.35)*'Bunker Sales'!F64 -> 2005.7832 | AX4: =(AX3/6.35)*'Bunker Sales'!F65 -> 2191.1486 | AY4: =(AY3/6.35)*'Bunker Sales'!F66 -> 2031.7249 | AZ4: =(AZ3/6.35)*'Bunker Sales'!F67 -> 2144.277 | BA4: =(BA3/6.35)*'Bunker Sales'!F68 -> 2207.2667 | BB4: =(BB3/6.35)*'Bunker Sales'!F69 -> 2358.1551 | BC4: =(BC3/6.35)*'Bunker Sales'!F70 -> 2420.732 | BD4: =(BD3/6.35)*'Bunker Sales'!F71 -> 2238.8033 | BE4: =(BE3/6.35)*'Bunker Sales'!F72 -> 2330.6198 | BF4: =(BF3/6.35)*'Bunker Sales'!F73 -> 2427.0432 | BG4: =(BG3/6.35)*'Bunker Sales'!F74 -> 1783.6458 | BH4: =(BH3/6.35)*'Bunker Sales'!F75 -> 2002.3316 | BI4: =(BI3/6.35)*'Bunker Sales'!F76 -> 2141.323 | BJ4: =(BJ3/6.35)*IFERROR(1*'Bunker Sales'!F77,0.56) -> 2164.5565 | BK4: =(BK3/6.35)*IFERROR(1*'Bunker Sales'!F78,0.56) -> 2066.2677 | BL4: =(BL3/6.35)*IFERROR(1*'Bunker Sales'!F79,0.56) -> 2072.0882 | BM4: =(BM3/6.35)*IFERROR(1*'Bunker Sales'!F80,0.56) -> 2039.9874 | BN4: =(BN3/6.35)*IFERROR(1*'Bunker Sales'!F81,0.56) -> 2039.2819 | BO4: =(BO3/6.35)*IFERROR(1*'Bunker Sales'!F82,0.56) -> 2041.1339 | BP4: =(BP3/6.35)*IFERROR(1*'Bunker Sales'!F83,0.56) -> 2021.7323 | BQ4: =(BQ3/6.35)*IFERROR(1*'Bunker Sales'!F84,0.56) -> 2004.7118 | BR4: =(BR3/6.35)*IFERROR(1*'Bunker Sales'!F85,0.56) -> 2271.3953
A5: Floating Stock | B5: ='Floating Storage'!Q3 -> 2557.161 | C5: ='Floating Storage'!R3 -> 2355.904 | D5: ='Floating Storage'!S3 -> 2999.022 | E5: ='Floating Storage'!T3 -> 3035.744 | F5: ='Floating Storage'!U3 -> 2507.033 | G5: ='Floating Storage'!V3 -> 2044.029 | H5: ='Floating Storage'!W3 -> 2070.344 | I5: ='Floating Storage'!X3 -> 1869.139 | ... BD5: ='Floating Storage'!BS3 -> 1537.274 | BE5: =BD5 -> 1537.274 | BF5: =BE5 -> 1537.274 | BG5: =BF5 -> 1537.274 | BH5: =BG5 -> 1537.274 | BI5: =BH5 -> 1537.274 | BJ5: 1508.5 | BK5: 1486.8 | BL5: 1465.1 | BM5: 1443.4 | BN5: 1421.7 | BO5: 1400 | BP5: 1400 | BQ5: 1400 | BR5: 1400
A6: Total Stock | B6: =B4+B5 -> 5355.2366 | C6: =C4+C5 -> 5426.3108 | D6: =D4+D5 -> 6032.4414 | E6: =E4+E5 -> 5791.0811 | F6: =F4+F5 -> 5051.7223 | G6: =G4+G5 -> 4767.1149 | H6: =H4+H5 -> 4528.6541 | I6: =I4+I5 -> 4451.8306 | ... BR6: =BR4+BR5 -> 3671.3953
A7: Stock Change | C7: =C6-B6 -> 71.074143 | D7: =D6-C6 -> 606.13058 | E7: =E6-D6 -> -241.36024 | F7: =F6-E6 -> -739.35886 | G7: =G6-F6 -> -284.60737 | H7: =H6-G6 -> -238.46079 | I7: =I6-H6 -> -76.82353 | J7: =J6-I6 -> -334.92751 | ... BR7: =BR6-BQ6 -> 266.68346
A8: Imports | B8: 1965.4136 | C8: 2480.4477 | D8: 2021.7271 | E8: 2549.106 | F8: 2645.7647 | G8: 3029.9259 | H8: 1863.0337 | I8: 2139.3772 | J8: 2560.7073 | K8: 1839.9396 | L8: 1501.2775 | M8: 1825.0955 | N8: 2138.3628 | O8: 2010.3046 | P8: 2351.084 | Q8: 2267.2601 | R8: 2185.8773 | S8: 2196.2793 | T8: 2247.7028 | U8: 2250.749 | V8: 2274.954 | W8: 1375.2934 | X8: 2646.2751 | Y8: 1577.9184 | Z8: 1360.5396 | AA8: 2685.6054 | AB8: 2588.5271 | AC8: 1703.9134 | AD8: 1929.7007 | AE8: 2049.5176 | AF8: 1936.6402 | AG8: 2197.8551 | AH8: 1954.6797 | AI8: 2485.3539 | AJ8: 1590.3913 | AK8: 2089.3441 | AL8: 1701.833 | AM8: 2017.4524 | AN8: 1376.9372 | AO8: 1565.7616 | AP8: 1341.0047 | AQ8: 1444.9437 | AR8: 2099.5375 | AS8: 2331.0104 | AT8: 1864.3147 | AU8: 1392.1014 | AV8: 1268.5922 | AW8: 1913.1609 | AX8: 1323.0883 | AY8: 1848.2866 | AZ8: 1471.8541 | BA8: 1922.6909 | BB8: 1808.5481 | BC8: 1623.2277 | BD8: 1556 | BE8: 1411 | BF8: 1628 | BG8: 1778 | BH8: 2361 | BI8: 831 | BJ8: =ROUND($B$24*F$31,0) -> 1683 | BK8: =ROUND($B$24*G$31,0) -> 1719 | BL8: =ROUND($B$24*H$31,0) -> 1947 | BM8: =ROUND($B$24*I$31,0) -> 1634 | BN8: =ROUND($B$24*J$31,0) -> 1668 | BO8: =ROUND($B$24*K$31,0) -> 1731 | BP8: =ROUND($B$24*L$31,0) -> 1834 | BQ8: =ROUND($B$24*M$31,0) -> 1664 | BR8: =ROUND($B$24*N$31,0) -> 1768
A9: Exports | B9: 1062.3174 | C9: 1554.7928 | D9: 1207.7443 | E9: 1561.4469 | F9: 1191.118 | G9: 960.99881 | H9: 891.78408 | I9: 1088.8398 | J9: 746.46272 | K9: 655.1924 | L9: 852.34611 | M9: 942.08438 | N9: 528.36704 | O9: 711.21581 | P9: 519.48851 | Q9: 569.64615 | R9: 717.61794 | S9: 542.69861 | T9: 595.71686 | U9: 666.1717 | V9: 615.91135 | W9: 765.09186 | X9: 528.32275 | Y9: 436.29978 | Z9: 449.5358 | AA9: 572.05218 | AB9: 709.76934 | AC9: 512.06785 | AD9: 807.28108 | AE9: 776.65412 | AF9: 826.11468 | AG9: 504.09086 | AH9: 675.70167 | AI9: 850.46599 | AJ9: 461.25926 | AK9: 761.04441 | AL9: 728.86162 | AM9: 788.87542 | AN9: 665.88638 | AO9: 367.25147 | AP9: 721.07197 | AQ9: 734.92995 | AR9: 730.83273 | AS9: 806.118 | AT9: 1070.8745 | AU9: 682.8161 | AV9: 327.93048 | AW9: 497 | AX9: 582 | AY9: 314 | AZ9: 442.25114 | BA9: 731 | BB9: 750.94098 | BC9: 702 | BD9: 845 | BE9: 687 | BF9: 492 | BG9: 944 | BH9: 583 | BI9: 516 | BJ9: =ROUND($B$25*F$32,0) -> 523 | BK9: =ROUND($B$25*G$32,0) -> 558 | BL9: =ROUND($B$25*H$32,0) -> 519 | BM9: =ROUND($B$25*I$32,0) -> 510 | BN9: =ROUND($B$25*J$32,0) -> 683 | BO9: =ROUND($B$25*K$32,0) -> 626 | BP9: =ROUND($B$25*L$32,0) -> 720 | BQ9: =ROUND($B$25*M$32,0) -> 670 | BR9: =ROUND($B$25*N$32,0) -> 683
A10: Net Imports | B10: =B8-B9 -> 903.0962 | C10: =C8-C9 -> 925.6549 | D10: =D8-D9 -> 813.98277 | E10: =E8-E9 -> 987.65915 | F10: =F8-F9 -> 1454.6467 | G10: =G8-G9 -> 2068.9271 | H10: =H8-H9 -> 971.24964 | I10: =I8-I9 -> 1050.5374 | ... BR10: =BR8-BR9 -> 1085
A11: Singapore Bunker Sales | B11: 2739.2975 | C11: 2739.2975 | D11: 2739.2975 | E11: 2739.2975 | F11: 2739.2975 | G11: 2739.2975 | H11: 2739.2975 | I11: 2739.2975 | J11: 2739.2975 | K11: 2499.5825 | L11: 2499.5825 | M11: 2499.5825 | N11: 2499.5825 | O11: 2499.5825 | P11: 2499.5825 | Q11: 2499.5825 | R11: 2499.5825 | S11: 2499.5825 | T11: 2499.5825 | U11: 2499.5825 | V11: 2499.5825 | W11: 2558.4467 | X11: 2558.4467 | Y11: 2558.4467 | Z11: 2558.4467 | AA11: 2558.4467 | AB11: 2558.4467 | AC11: 2558.4467 | AD11: 2558.4467 | AE11: 2558.4467 | AF11: 2558.4467 | AG11: 2558.4467 | AH11: 2558.4467 | AI11: 2861.13 | AJ11: 2554.63 | AK11: 2419.86 | AL11: 2252.43 | AM11: 2639.46 | AN11: 2331.06 | AO11: 2485.68 | AP11: 2444.39 | AQ11: 2248.03 | AR11: 2514.21 | AS11: 2398.35 | AT11: 2429.62 | AU11: 2431.31 | AV11: 2065.1 | AW11: 2331.88 | AX11: 2236.49 | AY11: 2453.97 | AZ11: 2311.01 | BA11: 2372.12 | BB11: 2500.97 | BC11: 2350 | BD11: 2433 | BE11: 2512 | BF11: 2830 | BG11: 2561 | BH11: 2310 | BI11: =BH11 -> 2310 | BJ11: =ROUND($B$27*F$34,0) -> 2328 | BK11: =ROUND($B$27*G$34,0) -> 2568 | BL11: =ROUND($B$27*H$34,0) -> 2443 | BM11: =ROUND($B$27*I$34,0) -> 2470 | BN11: =ROUND($B$27*J$34,0) -> 2613 | BO11: =ROUND($B$27*K$34,0) -> 2438 | BP11: =ROUND($B$27*L$34,0) -> 2500 | BQ11: =ROUND($B$27*M$34,0) -> 2575 | BR11: =ROUND($B$27*N$34,0) -> 2920
A12: Crude Imports | B12: 635.50281 | C12: 630.24866 | D12: 842.66521 | E12: 726.71019 | F12: 476.1475 | G12: 932.78357 | H12: 651.78095 | I12: 712.43739 | J12: 575.39534 | K12: 556.29195 | L12: 804.84034 | M12: 516.70101 | N12: 779.44515 | O12: 275.54228 | P12: 593.34296 | Q12: 317.49676 | R12: 421.04948 | S12: 923.72062 | T12: 479.80857 | U12: 667.81938 | V12: 789.77416 | W12: 399.9195 | X12: 581.7109 | Y12: 342.58133 | Z12: 618.4001 | AA12: 534.47934 | AB12: 674.77396 | AC12: 423.68973 | AD12: 704.16828 | AE12: 566.5015 | AF12: 521.93642 | AG12: 232.15152 | AH12: 742.48278 | AI12: 566.5015 | AJ12: 521.93642 | AK12: 232.15152 | AL12: 742.48278 | AM12: 862.22248 | AN12: 454.61259 | AO12: 850.74768 | AP12: 507.17462 | AQ12: 853.73258 | AR12: 679.40435 | AS12: 681.26644 | AT12: 541.48273 | AU12: 937.9026 | AV12: 702.0605 | AW12: 1096.565 | AX12: 699.64734 | AY12: 732.70095 | AZ12: 499.9153 | BA12: 638.70908 | BB12: 925 | BC12: 1064 | BD12: 1021 | BE12: ='Crude Imports'!B26 -> 618.4001 | BF12: ='Crude Imports'!B27 -> 534.47934 | BG12: ='Crude Imports'!B28 -> 674.77396 | BH12: =BG12 -> 674.77396 | BI12: =BH12 -> 674.77396 | BJ12: =ROUND($B$26*F$33,0) -> 740 | BK12: =ROUND($B$26*G$33,0) -> 620 | BL12: =ROUND($B$26*H$33,0) -> 651 | BM12: =ROUND($B$26*I$33,0) -> 647 | BN12: =ROUND($B$26*J$33,0) -> 665 | BO12: =ROUND($B$26*K$33,0) -> 896 | BP12: =ROUND($B$26*L$33,0) -> 705 | BQ12: =ROUND($B$26*M$33,0) -> 812 | BR12: =ROUND($B$26*N$33,0) -> 830
A13: Production | B13: 221.65 | C13: 226.2 | D13: 195 | E13: 182.65 | F13: 185.25 | G13: 202.15 | H13: 187.85 | I13: 137.8 | J13: 182.65 | K13: 279.5 | L13: 230.75 | M13: 290.55 | N13: 276.25 | O13: 298.35 | P13: 354.25 | Q13: 311.35 | R13: 317.2 | S13: 235.95 | T13: 338.65 | U13: 258.05 | V13: 242.45 | W13: 299 | X13: 285.35 | Y13: 269.1 | Z13: 285.35 | AA13: 258.05 | AB13: 269.1 | AC13: 258.7 | AD13: 304.2 | AE13: 295.1 | AF13: 273 | AG13: 408.2 | AH13: 373.75 | AI13: 363.35 | AJ13: 247.65 | AK13: 360.1 | AL13: 336.7 | AM13: 274.3 | AN13: 286 | AO13: 264.55 | AP13: 286 | AQ13: 332.15 | AR13: 330.2 | AS13: 280.8 | AT13: 274.3 | AU13: 284.7 | AV13: 288.6 | AW13: 372.45 | AX13: 313.3 | AY13: =Production!DV13 -> 187.2 | AZ13: =Production!DW13 -> 323.05 | BA13: =Production!DX13 -> 332.8 | BB13: =Production!DY13 -> 321.1 | BC13: =Production!DZ13 -> 300.3 | BD13: =Production!EA13 -> 258.7 | BE13: =Production!EB13 -> 248.95 | BF13: =Production!EC13 -> 246.35 | BG13: =Production!ED13 -> 125.45 | BH13: =AV13 -> 288.6 | BI13: =AW13 -> 372.45 | BJ13: =AX13 -> 313.3 | BK13: =AY13 -> 187.2 | BL13: =AZ13 -> 323.05 | BM13: =BA13 -> 332.8 | BN13: =BB13 -> 321.1 | BO13: =BC13 -> 300.3 | ... BR13: =BF13 -> 246.35
A14: Imports vs Bunker Sales | B14: =B10+B12-B11 -> -1200.6985 | C14: =C10+C12-C11 -> -1183.3939 | D14: =D10+D12-D11 -> -1082.6495 | E14: =E10+E12-E11 -> -1024.9282 | F14: =F10+F12-F11 -> -808.50325 | G14: =G10+G12-G11 -> 262.4132 | H14: =H10+H12-H11 -> -1116.2669 | I14: =I10+I12-I11 -> -976.32274 | ... BR14: =BR10+BR12-BR11 -> -1005
A15: Net Move vs Stock Move
A16: Predicted Stock | C16: =B6+C10+C13-C11+C12 -> 4398.0427 | D16: =C6+D10+D13-D11+D12 -> 4538.6613 | E16: =D6+E10+E13-E11+E12 -> 5190.1632 | F16: =E6+F10+F13-F11+F12 -> 5167.8279 | G16: =F6+G10+G13-G11+G12 -> 5516.2855 | H16: =G6+H10+H13-H11+H12 -> 3838.698 | I16: =H6+I10+I13-I11+I12 -> 3690.1314 | J16: =I6+J10+J13-J11+J12 -> 4284.823 | ... BR16: =BQ6+BR10+BR13-BR11+BR12 -> 2646.0618
A17: Diff to actual | C17: =IF(C6=0,"",C16-C6) -> -1028.2681 | D17: =IF(D6=0,"",D16-D6) -> -1493.7801 | E17: =IF(E6=0,"",E16-E6) -> -600.91793 | F17: =IF(F6=0,"",F16-F6) -> 116.1056 | G17: =IF(G6=0,"",G16-G6) -> 749.17056 | H17: =IF(H6=0,"",H16-H6) -> -689.95612 | I17: =IF(I6=0,"",I16-I6) -> -761.69921 | J17: =IF(J6=0,"",J16-J6) -> 167.91992 | ... BR17: =IF(BR6=0,"",BR16-BR6) -> -1025.3335
A18: Predicted MoM Stock Change | C18: =C16-B16 -> 4398.0427 | D18: =D16-C16 -> 140.61857 | E18: =E16-D16 -> 651.50194 | F18: =F16-E16 -> -22.335324 | G18: =G16-F16 -> 348.45759 | H18: =H16-G16 -> -1677.5875 | I18: =I16-H16 -> -148.56662 | J18: =J16-I16 -> 594.69163 | ... BR18: =BR16-BQ16 -> -255.62047
A19: Diff to Actual | B19: =IF(B7="","",B18-B7) | C19: =IF(C7="","",C18-C7) -> 4326.9685 | D19: =IF(D7="","",D18-D7) -> -465.51201 | E19: =IF(E7="","",E18-E7) -> 892.86217 | F19: =IF(F7="","",F18-F7) -> 717.02353 | G19: =IF(G7="","",G18-G7) -> 633.06496 | H19: =IF(H7="","",H18-H7) -> -1439.1267 | I19: =IF(I7="","",I18-I7) -> -71.743091 | ... BR19: =IF(BR7="","",BR18-BR7) -> -522.30394
C20: =(C16-C6)/C6 -> -0.18949672 | D20: =(D16-D6)/D6 -> -0.24762447 | E20: =(E16-E6)/E6 -> -0.1037661 | F20: =(F16-F6)/F6 -> 0.02298337 | G20: =(G16-G6)/G6 -> 0.15715387 | H20: =(H16-H6)/H6 -> -0.15235346 | I20: =(I16-I6)/I6 -> -0.17109798 | J20: =(J16-J6)/J6 -> 0.040787922 | ... BR20: =(BR16-BR6)/BR6 -> -0.27927624
